Workbook

Sheet ВВОД
B2: Наименование станции | C2: Насос | D2: Артикул | E2: Размеры | G2: Q | H2: H | I2: P2 | J2: NPSH | K2: КПД
B3: Hydro-FS-A 1/1 CRV 10-1 G2-B-80-16 | C3: {=IFERROR(INDEX(HFS_CRV!$B:$B, MATCH($B$3, HFS_CRV!$A:$A, 0)), "СТАНЦИЯ НЕ НАЙДЕНА")} -> CRV 10-1C | D3: {=IFERROR(INDEX(HFS_CRV!$AE:$AE, MATCH($B$3, HFS_CRV!$A:$A, 0)), "СТАНЦИЯ НЕ НАЙДЕНА")} -> 75211384 | E3: {=TRANSPOSE(HFS_CRV!$C$1:$V$1)} -> В | F3: {=IFERROR(TRANSPOSE(INDEX(HFS_CRV!$C:$V, MATCH($B$3, HFS_CRV!$A:$A, 0), 0)), "")} -> 1650 | G3: {=IFERROR(TRANSPOSE(INDEX(CRV!$C:$L, MATCH($C$3, CRV!$A:$A, 0), 0)), "")} -> 0 | H3: {=IFERROR(TRANSPOSE(INDEX(CRV!$M:$V, MATCH($C$3, CRV!$A:$A, 0), 0)), "")} -> 13.75 | I3: {=IFERROR(TRANSPOSE(INDEX(CRV!$W:$AF, MATCH($C$3, CRV!$A:$A, 0), 0)), "")} -> 0.102 | J3: {=IFERROR(TRANSPOSE(INDEX(CRV!$AG:$AP, MATCH($C$3, CRV!$A:$A, 0), 0)), "")} -> 0.427 | K3: {=IFERROR(TRANSPOSE(INDEX(CRV!$AQ:$AZ, MATCH($C$3, CRV!$A:$A, 0), 0)), "")} -> 0
E4: В1 | F4: 613 | G4: 5 | H4: 11.45 | I4: 0.242 | J4: 0.948 | K4: 54
B5: Max расход: | E5: В2 | F5: 180 | G5: 7 | H5: 10.4 | I5: 0.2843 | J5: 1.241 | K5: 63.51
B6: Max напор: | E6: Ш1 | F6: 565 | G6: 8 | H6: 9.85 | I6: 0.2993 | J6: 1.449 | K6: 66.12
B7: Номинальный напор: | E7: Ш2 | F7: 520 | G7: 9 | H7: 9.25 | I7: 0.3105 | J7: 1.709 | K7: 68.06
B8: Количество насосов: | E8: Ш3 | F8: 1549 | G8: 10 | H8: 8.65 | I8: 0.3178 | J8: 2.067 | K8: 69.23
B9: Количество резервных насосов: | E9: Шобщ | F9: 1085 | G9: 11 | H9: 8 | I9: 0.3208 | J9: 2.553 | K9: 69.5
B10: Тип установки уплотнения: | E10: Р1 | F10: 1760 | G10: 12 | H10: 7.35 | I10: 0.3192 | J10: 3.094 | K10: 68.65
E11: Р2 | F11: 427 | G11: 13 | H11: 6.5994643 | I11: 0.3124 | J11: 3.68 | K11: 66.3
B12: Корпус: | E12: Р3 | G12: 14 | H12: 5.82 | I12: 0.2996 | J12: 4.326 | K12: 61.81
B13: Рабочее колесо: | E13: Р4
B14: Уплотнение вала: | E14: РП | F14: 385
B15: Коллектор: | E15: РВ | F15: 100
E16: ПАЗ
B17: Температура окружающей среды: | E17: ОТВ-Е | F17: 12 отв. ø16
B18: Относительная влажность воздуха: | E18: ВШ | F18: 1000
B19: Max рабочее давление: | E19: ШШ | F19: 800
B20: Стандарт трубного присоединения: | E20: ШО | F20: 860
B21: Размер всасывающего патрубка: | E21: К | F21: 450
B22: Размер напорного патрубка: | E22: DN | F22: 80
B23: Допустимое давление фланцев:
B25: Диапазон температуры жидкости:
B27: Мощность (P2) одного насоса:
B28: Номинальное напряжение:
B29: Max потребление тока:
B30: Схема пуска:
B31: Степень защиты (IEC 34-5):
B33: Температура хранения:
B34: Масса (нетто):
B35: Масса (брутто):

Sheet HFS_CRV
A1: Наименование | B1: Насос | C1: В | D1: В1 | E1: В2 | F1: Ш1 | G1: Ш2 | H1: Ш3 | I1: Шобщ | J1: Р1 | K1: Р2 | L1: Р3 | M1: Р4 | N1: РП | O1: РВ | P1: ПАЗ | Q1: ОТВ-Е | R1: ВШ | S1: ШШ | T1: ШО | U1: К | V1: DN | W1: Общее кол-во | X1: Основа | Y1: Резерв | Z1: Мощность | AA1: Ток | AB1: Схема пуска | AC1: Торцевое | AD1: Масса нетто | AE1: Артикул
A2: Hydro-FS-A 1/1 CRV 10-1 G2-B-80-16 | B2: =IFERROR(__xludf.DUMMYFUNCTION("IFERROR(IF(REGEXMATCH(REGEXEXTRACT(A2,""\bCRV\s*\d+(?:-\d+)+(?:-(?:A?BI|AI|BI))?\b""),""-(?:A?BI|AI|BI)$""),REGEXREPLACE(REGEXEXTRACT(A2,""\bCRV\s*\d+(?:-\d+)+(?:-(?:A?BI|AI|BI))?\b""),""-(A?BI|AI|BI)$"",""C$1""),REGEXEXTRACT(A2,""\bCRV\s*\d+(?:-\d+)+(?:-"&"(?:A?BI|AI|BI))?\b"")&""C""),"""")"),"CRV 10-1C") -> CRV 10-1C | C2: 1650 | D2: {=IFERROR(XLOOKUP($B2,CRV!$A:$A,CRV!$BA:$BA)+XLOOKUP($B2,CRV!$A:$A,CRV!$BB:$BB)+$O2,"")} -> 613 | E2: 180 | F2: 565 | G2: 520 | H2: 1549 | I2: 1085 | J2: 1760 | K2: 427 | N2: 385 | O2: 100 | Q2: 12 отв. ø16 | R2: 1000 | S2: 800 | T2: 860 | U2: 450 | V2: =IFERROR(__xludf.DUMMYFUNCTION("IFERROR(REGEXEXTRACT(A2,""G2-B-(\d+)""),"""")"),"80") -> 80 | W2: =IF(OR(X2="", Y2=""), "", X2+Y2) -> 2 | X2: =IFERROR(__xludf.DUMMYFUNCTION("IFERROR(VALUE(REGEXEXTRACT(A2,""\b(\d+)/\d+\b"")),"""")"),1.0) -> 1 | Y2: =IFERROR(__xludf.DUMMYFUNCTION("IFERROR(VALUE(REGEXEXTRACT(A2,""\b\d+/(\d+)\b"")),"""") "),1.0) -> 1 | Z2: {=IFERROR(INDEX(CRV!BU:BU, MATCH(B2, CRV!A:A, 0)), "")} -> 0.37 | AA2: {=IFERROR(INDEX(CRV!BV:BV, MATCH(B2, CRV!A:A, 0))*X2+4.5*2+7, "")} -> 17.6 | AB2: {=IFERROR(IF(VALUE(XLOOKUP($B2,CRV!$A:$A,CRV!$BU:$BU))<=5.5,"прямой пуск (DOL)","звезда-треугольник (SD)"),"")} -> прямой пуск (DOL) | AC2: {=IFERROR(INDEX(CRV!CA:CA, MATCH(B2, CRV!A:A, 0)), "")} -> HQQE | AD2: 239 | AE2: 75211384
A3: Hydro-FS-A 1/1 CRV 10-2 G2-B-80-16 | B3: =IFERROR(__xludf.DUMMYFUNCTION("IFERROR(IF(REGEXMATCH(REGEXEXTRACT(A3,""\bCRV\s*\d+(?:-\d+)+(?:-(?:A?BI|AI|BI))?\b""),""-(?:A?BI|AI|BI)$""),REGEXREPLACE(REGEXEXTRACT(A3,""\bCRV\s*\d+(?:-\d+)+(?:-(?:A?BI|AI|BI))?\b""),""-(A?BI|AI|BI)$"",""C$1""),REGEXEXTRACT(A3,""\bCRV\s*\d+(?:-\d+)+(?:-"&"(?:A?BI|AI|BI))?\b"")&""C""),"""")"),"CRV 10-2C") -> CRV 10-2C | C3: 1650 | D3: {=IFERROR(XLOOKUP($B3,CRV!$A:$A,CRV!$BA:$BA)+XLOOKUP($B3,CRV!$A:$A,CRV!$BB:$BB)+$O3,"")} -> 643 | E3: 180 | F3: 565 | G3: 520 | H3: 1549 | I3: 1085 | J3: 1760 | K3: 427 | N3: 385 | O3: 100 | Q3: 12 отв. ø16 | R3: 1000 | S3: 800 | T3: 860 | U3: 450 | V3: =IFERROR(__xludf.DUMMYFUNCTION("IFERROR(REGEXEXTRACT(A3,""G2-B-(\d+)""),"""")"),"80") -> 80 | W3: =IF(OR(X3="", Y3=""), "", X3+Y3) -> 2 | X3: =IFERROR(__xludf.DUMMYFUNCTION("IFERROR(VALUE(REGEXEXTRACT(A3,""\b(\d+)/\d+\b"")),"""")"),1.0) -> 1 | Y3: =IFERROR(__xludf.DUMMYFUNCTION("IFERROR(VALUE(REGEXEXTRACT(A3,""\b\d+/(\d+)\b"")),"""") "),1.0) -> 1 | Z3: {=IFERROR(INDEX(CRV!BU:BU, MATCH(B3, CRV!A:A, 0)), "")} -> 0.75 | AA3: {=IFERROR(INDEX(CRV!BV:BV, MATCH(B3, CRV!A:A, 0))*X3+4.5*2+7, "")} -> 19 | AB3: {=IFERROR(IF(VALUE(XLOOKUP($B3,CRV!$A:$A,CRV!$BU:$BU))<=5.5,"прямой пуск (DOL)","звезда-треугольник (SD)"),"")} -> прямой пуск (DOL) | AC3: {=IFERROR(INDEX(CRV!CA:CA, MATCH(B3, CRV!A:A, 0)), "")} -> HQQE | AD3: 243 | AE3: 75211387
A4: Hydro-FS-A 1/1 CRV 10-3 G2-B-80-16 | B4: =IFERROR(__xludf.DUMMYFUNCTION("IFERROR(IF(REGEXMATCH(REGEXEXTRACT(A4,""\bCRV\s*\d+(?:-\d+)+(?:-(?:A?BI|AI|BI))?\b""),""-(?:A?BI|AI|BI)$""),REGEXREPLACE(REGEXEXTRACT(A4,""\bCRV\s*\d+(?:-\d+)+(?:-(?:A?BI|AI|BI))?\b""),""-(A?BI|AI|BI)$"",""C$1""),REGEXEXTRACT(A4,""\bCRV\s*\d+(?:-\d+)+(?:-"&"(?:A?BI|AI|BI))?\b"")&""C""),"""")"),"CRV 10-3C") -> CRV 10-3C | C4: 1650 | D4: {=IFERROR(XLOOKUP($B4,CRV!$A:$A,CRV!$BA:$BA)+XLOOKUP($B4,CRV!$A:$A,CRV!$BB:$BB)+$O4,"")} -> 710 | E4: 180 | F4: 565 | G4: 520 | H4: 1549 | I4: 1085 | J4: 1760 | K4: 427 | N4: 385 | O4: 100 | Q4: 12 отв. ø16 | R4: 1000 | S4: 800 | T4: 860 | U4: 450 | V4: =IFERROR(__xludf.DUMMYFUNCTION("IFERROR(REGEXEXTRACT(A4,""G2-B-(\d+)""),"""")"),"80") -> 80 | W4: =IF(OR(X4="", Y4=""), "", X4+Y4) -> 2 | X4: =IFERROR(__xludf.DUMMYFUNCTION("IFERROR(VALUE(REGEXEXTRACT(A4,""\b(\d+)/\d+\b"")),"""")"),1.0) -> 1 | Y4: =IFERROR(__xludf.DUMMYFUNCTION("IFERROR(VALUE(REGEXEXTRACT(A4,""\b\d+/(\d+)\b"")),"""") "),1.0) -> 1 | Z4: {=IFERROR(INDEX(CRV!BU:BU, MATCH(B4, CRV!A:A, 0)), "")} -> 1.1 | AA4: {=IFERROR(INDEX(CRV!BV:BV, MATCH(B4, CRV!A:A, 0))*X4+4.5*2+7, "")} -> 20.2 | AB4: {=IFERROR(IF(VALUE(XLOOKUP($B4,CRV!$A:$A,CRV!$BU:$BU))<=5.5,"прямой пуск (DOL)","звезда-треугольник (SD)"),"")} -> прямой пуск (DOL) | AC4: {=IFERROR(INDEX(CRV!CA:CA, MATCH(B4, CRV!A:A, 0)), "")} -> HQQE | AD4: 251 | AE4: 75211388
A5: Hydro-FS-A 1/1 CRV 10-4 G2-B-80-16 | B5: =IFERROR(__xludf.DUMMYFUNCTION("IFERROR(IF(REGEXMATCH(REGEXEXTRACT(A5,""\bCRV\s*\d+(?:-\d+)+(?:-(?:A?BI|AI|BI))?\b""),""-(?:A?BI|AI|BI)$""),REGEXREPLACE(REGEXEXTRACT(A5,""\bCRV\s*\d+(?:-\d+)+(?:-(?:A?BI|AI|BI))?\b""),""-(A?BI|AI|BI)$"",""C$1""),REGEXEXTRACT(A5,""\bCRV\s*\d+(?:-\d+)+(?:-"&"(?:A?BI|AI|BI))?\b"")&""C""),"""")"),"CRV 10-4C") -> CRV 10-4C | C5: 1650 | D5: {=IFERROR(XLOOKUP($B5,CRV!$A:$A,CRV!$BA:$BA)+XLOOKUP($B5,CRV!$A:$A,CRV!$BB:$BB)+$O5,"")} -> 740 | E5: 180 | F5: 565 | G5: 520 | H5: 1549 | I5: 1085 | J5: 1760 | K5: 427 | N5: 385 | O5: 100 | Q5: 12 отв. ø16 | R5: 1000 | S5: 800 | T5: 860 | U5: 450 | V5: =IFERROR(__xludf.DUMMYFUNCTION("IFERROR(REGEXEXTRACT(A5,""G2-B-(\d+)""),"""")"),"80") -> 80 | W5: =IF(OR(X5="", Y5=""), "", X5+Y5) -> 2 | X5: =IFERROR(__xludf.DUMMYFUNCTION("IFERROR(VALUE(REGEXEXTRACT(A5,""\b(\d+)/\d+\b"")),"""")"),1.0) -> 1 | Y5: =IFERROR(__xludf.DUMMYFUNCTION("IFERROR(VALUE(REGEXEXTRACT(A5,""\b\d+/(\d+)\b"")),"""") "),1.0) -> 1 | Z5: {=IFERROR(INDEX(CRV!BU:BU, MATCH(B5, CRV!A:A, 0)), "")} -> 1.5 | AA5: {=IFERROR(INDEX(CRV!BV:BV, MATCH(B5, CRV!A:A, 0))*X5+4.5*2+7, "")} -> 21.6 | AB5: {=IFERROR(IF(VALUE(XLOOKUP($B5,CRV!$A:$A,CRV!$BU:$BU))<=5.5,"прямой пуск (DOL)","звезда-треугольник (SD)"),"")} -> прямой пуск (DOL) | AC5: {=IFERROR(INDEX(CRV!CA:CA, MATCH(B5, CRV!A:A, 0)), "")} -> HQQE | AD5: 267 | AE5: 75211385
A6: Hydro-FS-A 1/1 CRV 10-5 G2-B-80-16 | B6: =IFERROR(__xludf.DUMMYFUNCTION("IFERROR(IF(REGEXMATCH(REGEXEXTRACT(A6,""\bCRV\s*\d+(?:-\d+)+(?:-(?:A?BI|AI|BI))?\b""),""-(?:A?BI|AI|BI)$""),REGEXREPLACE(REGEXEXTRACT(A6,""\bCRV\s*\d+(?:-\d+)+(?:-(?:A?BI|AI|BI))?\b""),""-(A?BI|AI|BI)$"",""C$1""),REGEXEXTRACT(A6,""\bCRV\s*\d+(?:-\d+)+(?:-"&"(?:A?BI|AI|BI))?\b"")&""C""),"""")"),"CRV 10-5C") -> CRV 10-5C | C6: 1650 | D6: {=IFERROR(XLOOKUP($B6,CRV!$A:$A,CRV!$BA:$BA)+XLOOKUP($B6,CRV!$A:$A,CRV!$BB:$BB)+$O6,"")} -> 822 | E6: 180 | F6: 565 | G6: 520 | H6: 1549 | I6: 1085 | J6: 1760 | K6: 427 | N6: 385 | O6: 100 | Q6: 12 отв. ø16 | R6: 1000 | S6: 800 | T6: 860 | U6: 450 | V6: =IFERROR(__xludf.DUMMYFUNCTION("IFERROR(REGEXEXTRACT(A6,""G2-B-(\d+)""),"""")"),"80") -> 80 | W6: =IF(OR(X6="", Y6=""), "", X6+Y6) -> 2 | X6: =IFERROR(__xludf.DUMMYFUNCTION("IFERROR(VALUE(REGEXEXTRACT(A6,""\b(\d+)/\d+\b"")),"""")"),1.0) -> 1 | Y6: =IFERROR(__xludf.DUMMYFUNCTION("IFERROR(VALUE(REGEXEXTRACT(A6,""\b\d+/(\d+)\b"")),"""") "),1.0) -> 1 | Z6: {=IFERROR(INDEX(CRV!BU:BU, MATCH(B6, CRV!A:A, 0)), "")} -> 2.2 | AA6: {=IFERROR(INDEX(CRV!BV:BV, MATCH(B6, CRV!A:A, 0))*X6+4.5*2+7, "")} -> 23.9 | AB6: {=IFERROR(IF(VALUE(XLOOKUP($B6,CRV!$A:$A,CRV!$BU:$BU))<=5.5,"прямой пуск (DOL)","звезда-треугольник (SD)"),"")} -> прямой пуск (DOL) | AC6: {=IFERROR(INDEX(CRV!CA:CA, MATCH(B6, CRV!A:A, 0)), "")} -> HQQE | AD6: 269 | AE6: 75211371
A7: Hydro-FS-A 1/1 CRV 10-6 G2-B-80-16 | B7: =IFERROR(__xludf.DUMMYFUNCTION("IFERROR(IF(REGEXMATCH(REGEXEXTRACT(A7,""\bCRV\s*\d+(?:-\d+)+(?:-(?:A?BI|AI|BI))?\b""),""-(?:A?BI|AI|BI)$""),REGEXREPLACE(REGEXEXTRACT(A7,""\bCRV\s*\d+(?:-\d+)+(?:-(?:A?BI|AI|BI))?\b""),""-(A?BI|AI|BI)$"",""C$1""),REGEXEXTRACT(A7,""\bCRV\s*\d+(?:-\d+)+(?:-"&"(?:A?BI|AI|BI))?\b"")&""C""),"""")"),"CRV 10-6C") -> CRV 10-6C | C7: 1650 | D7: {=IFERROR(XLOOKUP($B7,CRV!$A:$A,CRV!$BA:$BA)+XLOOKUP($B7,CRV!$A:$A,CRV!$BB:$BB)+$O7,"")} -> 852 | E7: 180 | F7: 565 | G7: 520 | H7: 1549 | I7: 1085 | J7: 1760 | K7: 427 | N7: 385 | O7: 100 | Q7: 12 отв. ø16 | R7: 1000 | S7: 800 | T7: 860 | U7: 450 | V7: =IFERROR(__xludf.DUMMYFUNCTION("IFERROR(REGEXEXTRACT(A7,""G2-B-(\d+)""),"""")"),"80") -> 80 | W7: =IF(OR(X7="", Y7=""), "", X7+Y7) -> 2 | X7: =IFERROR(__xludf.DUMMYFUNCTION("IFERROR(VALUE(REGEXEXTRACT(A7,""\b(\d+)/\d+\b"")),"""")"),1.0) -> 1 | Y7: =IFERROR(__xludf.DUMMYFUNCTION("IFERROR(VALUE(REGEXEXTRACT(A7,""\b\d+/(\d+)\b"")),"""") "),1.0) -> 1 | Z7: {=IFERROR(INDEX(CRV!BU:BU, MATCH(B7, CRV!A:A, 0)), "")} -> 2.2 | AA7: {=IFERROR(INDEX(CRV!BV:BV, MATCH(B7, CRV!A:A, 0))*X7+4.5*2+7, "")} -> 23.9 | AB7: {=IFERROR(IF(VALUE(XLOOKUP($B7,CRV!$A:$A,CRV!$BU:$BU))<=5.5,"прямой пуск (DOL)","звезда-треугольник (SD)"),"")} -> прямой пуск (DOL) | AC7: {=IFERROR(INDEX(CRV!CA:CA, MATCH(B7, CRV!A:A, 0)), "")} -> HQQE | AD7: 271 | AE7: 75211389
A8: Hydro-FS-A 1/1 CRV 10-9 G2-B-80-16 | B8: =IFERROR(__xludf.DUMMYFUNCTION("IFERROR(IF(REGEXMATCH(REGEXEXTRACT(A8,""\bCRV\s*\d+(?:-\d+)+(?:-(?:A?BI|AI|BI))?\b""),""-(?:A?BI|AI|BI)$""),REGEXREPLACE(REGEXEXTRACT(A8,""\bCRV\s*\d+(?:-\d+)+(?:-(?:A?BI|AI|BI))?\b""),""-(A?BI|AI|BI)$"",""C$1""),REGEXEXTRACT(A8,""\bCRV\s*\d+(?:-\d+)+(?:-"&"(?:A?BI|AI|BI))?\b"")&""C""),"""")"),"CRV 10-9C") -> CRV 10-9C | C8: 1650 | D8: {=IFERROR(XLOOKUP($B8,CRV!$A:$A,CRV!$BA:$BA)+XLOOKUP($B8,CRV!$A:$A,CRV!$BB:$BB)+$O8,"")} -> 962 | E8: 180 | F8: 565 | G8: 520 | H8: 1549 | I8: 1085 | J8: 1760 | K8: 427 | N8: 385 | O8: 100 | Q8: 12 отв. ø16 | R8: 1000 | S8: 800 | T8: 860 | U8: 450 | V8: =IFERROR(__xludf.DUMMYFUNCTION("IFERROR(REGEXEXTRACT(A8,""G2-B-(\d+)""),"""")"),"80") -> 80 | W8: =IF(OR(X8="", Y8=""), "", X8+Y8) -> 2 | X8: =IFERROR(__xludf.DUMMYFUNCTION("IFERROR(VALUE(REGEXEXTRACT(A8,""\b(\d+)/\d+\b"")),"""")"),1.0) -> 1 | Y8: =IFERROR(__xludf.DUMMYFUNCTION("IFERROR(VALUE(REGEXEXTRACT(A8,""\b\d+/(\d+)\b"")),"""") "),1.0) -> 1 | Z8: {=IFERROR(INDEX(CRV!BU:BU, MATCH(B8, CRV!A:A, 0)), "")} -> 3 | AA8: {=IFERROR(INDEX(CRV!BV:BV, MATCH(B8, CRV!A:A, 0))*X8+4.5*2+7, "")} -> 26.4 | AB8: {=IFERROR(IF(VALUE(XLOOKUP($B8,CRV!$A:$A,CRV!$BU:$BU))<=5.5,"прямой пуск (DOL)","звезда-треугольник (SD)"),"")} -> прямой пуск (DOL) | AC8: {=IFERROR(INDEX(CRV!CA:CA, MATCH(B8, CRV!A:A, 0)), "")} -> HQQE | AD8: 287 | AE8: 75211376
A9: Hydro-FS-A 1/1 CRV 10-12 G2-B-80-16 | B9: =IFERROR(__xludf.DUMMYFUNCTION("IFERROR(IF(REGEXMATCH(REGEXEXTRACT(A9,""\bCRV\s*\d+(?:-\d+)+(?:-(?:A?BI|AI|BI))?\b""),""-(?:A?BI|AI|BI)$""),REGEXREPLACE(REGEXEXTRACT(A9,""\bCRV\s*\d+(?:-\d+)+(?:-(?:A?BI|AI|BI))?\b""),""-(A?BI|AI|BI)$"",""C$1""),REGEXEXTRACT(A9,""\bCRV\s*\d+(?:-\d+)+(?:-"&"(?:A?BI|AI|BI))?\b"")&""C""),"""")"),"CRV 10-12C") -> CRV 10-12C | C9: 1650 | D9: {=IFERROR(XLOOKUP($B9,CRV!$A:$A,CRV!$BA:$BA)+XLOOKUP($B9,CRV!$A:$A,CRV!$BB:$BB)+$O9,"")} -> 1085 | E9: 180 | F9: 565 | G9: 520 | H9: 1549 | I9: 1085 | J9: 1760 | K9: 427 | N9: 385 | O9: 100 | Q9: 12 отв. ø16 | R9: 1000 | S9: 800 | T9: 860 | U9: 450 | V9: =IFERROR(__xludf.DUMMYFUNCTION("IFERROR(REGEXEXTRACT(A9,""G2-B-(\d+)""),"""")"),"80") -> 80 | W9: =IF(OR(X9="", Y9=""), "", X9+Y9) -> 2 | X9: =IFERROR(__xludf.DUMMYFUNCTION("IFERROR(VALUE(REGEXEXTRACT(A9,""\b(\d+)/\d+\b"")),"""")"),1.0) -> 1 | Y9: =IFERROR(__xludf.DUMMYFUNCTION("IFERROR(VALUE(REGEXEXTRACT(A9,""\b\d+/(\d+)\b"")),"""") "),1.0) -> 1 | Z9: {=IFERROR(INDEX(CRV!BU:BU, MATCH(B9, CRV!A:A, 0)), "")} -> 4 | AA9: {=IFERROR(INDEX(CRV!BV:BV, MATCH(B9, CRV!A:A, 0))*X9+4.5*2+7, "")} -> 23.8 | AB9: {=IFERROR(IF(VALUE(XLOOKUP($B9,CRV!$A:$A,CRV!$BU:$BU))<=5.5,"прямой пуск (DOL)","звезда-треугольник (SD)"),"")} -> прямой пуск (DOL) | AC9: {=IFERROR(INDEX(CRV!CA:CA, MATCH(B9, CRV!A:A, 0)), "")} -> HQQE | AD9: 315 | AE9: 75211390
A10: Hydro-FS-A 1/1 CRV 10-14 G2-B-80-16 | B10: =IFERROR(__xludf.DUMMYFUNCTION("IFERROR(IF(REGEXMATCH(REGEXEXTRACT(A10,""\bCRV\s*\d+(?:-\d+)+(?:-(?:A?BI|AI|BI))?\b""),""-(?:A?BI|AI|BI)$""),REGEXREPLACE(REGEXEXTRACT(A10,""\bCRV\s*\d+(?:-\d+)+(?:-(?:A?BI|AI|BI))?\b""),""-(A?BI|AI|BI)$"",""C$1""),REGEXEXTRACT(A10,""\bCRV\s*\d+(?:-\d+)+("&"?:-(?:A?BI|AI|BI))?\b"")&""C""),"""")"),"CRV 10-14C") -> CRV 10-14C | C10: 1650 | D10: {=IFERROR(XLOOKUP($B10,CRV!$A:$A,CRV!$BA:$BA)+XLOOKUP($B10,CRV!$A:$A,CRV!$BB:$BB)+$O10,"")} -> 1226 | E10: 180 | F10: 565 | G10: 520 | H10: 1549 | I10: 1085 | J10: 1760 | K10: 427 | N10: 385 | O10: 100 | Q10: 12 отв. ø16 | R10: 1000 | S10: 800 | T10: 860 | U10: 450 | V10: =IFERROR(__xludf.DUMMYFUNCTION("IFERROR(REGEXEXTRACT(A10,""G2-B-(\d+)""),"""")"),"80") -> 80 | W10: =IF(OR(X10="", Y10=""), "", X10+Y10) -> 2 | X10: =IFERROR(__xludf.DUMMYFUNCTION("IFERROR(VALUE(REGEXEXTRACT(A10,""\b(\d+)/\d+\b"")),"""")"),1.0) -> 1 | Y10: =IFERROR(__xludf.DUMMYFUNCTION("IFERROR(VALUE(REGEXEXTRACT(A10,""\b\d+/(\d+)\b"")),"""") "),1.0) -> 1 | Z10: {=IFERROR(INDEX(CRV!BU:BU, MATCH(B10, CRV!A:A, 0)), "")} -> 5.5 | AA10: {=IFERROR(INDEX(CRV!BV:BV, MATCH(B10, CRV!A:A, 0))*X10+4.5*2+7, "")} -> 26.6 | AB10: {=IFERROR(IF(VALUE(XLOOKUP($B10,CRV!$A:$A,CRV!$BU:$BU))<=5.5,"прямой пуск (DOL)","звезда-треугольник (SD)"),"")} -> прямой пуск (DOL) | AC10: {=IFERROR(INDEX(CRV!CA:CA, MATCH(B10, CRV!A:A, 0)), "")} -> HQQE | AD10: 359 | AE10: 75211391
A11: Hydro-FS-A 1/1 CRV 10-16 G2-B-80-25 | B11: =IFERROR(__xludf.DUMMYFUNCTION("IFERROR(IF(REGEXMATCH(REGEXEXTRACT(A11,""\bCRV\s*\d+(?:-\d+)+(?:-(?:A?BI|AI|BI))?\b""),""-(?:A?BI|AI|BI)$""),REGEXREPLACE(REGEXEXTRACT(A11,""\bCRV\s*\d+(?:-\d+)+(?:-(?:A?BI|AI|BI))?\b""),""-(A?BI|AI|BI)$"",""C$1""),REGEXEXTRACT(A11,""\bCRV\s*\d+(?:-\d+)+("&"?:-(?:A?BI|AI|BI))?\b"")&""C""),"""")"),"CRV 10-16C") -> CRV 10-16C | C11: 1650 | D11: {=IFERROR(XLOOKUP($B11,CRV!$A:$A,CRV!$BA:$BA)+XLOOKUP($B11,CRV!$A:$A,CRV!$BB:$BB)+$O11,"")} -> 1286 | E11: 180 | F11: 565 | G11: 520 | H11: 1549 | I11: 1085 | J11: 1760 | K11: 427 | N11: 385 | O11: 100 | Q11: 12 отв. ø16 | R11: 1000 | S11: 800 | T11: 860 | U11: 450 | V11: =IFERROR(__xludf.DUMMYFUNCTION("IFERROR(REGEXEXTRACT(A11,""G2-B-(\d+)""),"""")"),"80") -> 80 | W11: =IF(OR(X11="", Y11=""), "", X11+Y11) -> 2 | X11: =IFERROR(__xludf.DUMMYFUNCTION("IFERROR(VALUE(REGEXEXTRACT(A11,""\b(\d+)/\d+\b"")),"""")"),1.0) -> 1 | Y11: =IFERROR(__xludf.DUMMYFUNCTION("IFERROR(VALUE(REGEXEXTRACT(A11,""\b\d+/(\d+)\b"")),"""") "),1.0) -> 1 | Z11: {=IFERROR(INDEX(CRV!BU:BU, MATCH(B11, CRV!A:A, 0)), "")} -> 5.5 | AA11: {=IFERROR(INDEX(CRV!BV:BV, MATCH(B11, CRV!A:A, 0))*X11+4.5*2+7, "")} -> 26.6 | AB11: {=IFERROR(IF(VALUE(XLOOKUP($B11,CRV!$A:$A,CRV!$BU:$BU))<=5.5,"прямой пуск (DOL)","звезда-треугольник (SD)"),"")} -> прямой пуск (DOL) | AC11: {=IFERROR(INDEX(CRV!CA:CA, MATCH(B11, CRV!A:A, 0)), "")} -> HQQE | AD11: {=IFERROR(AD10-W11*XLOOKUP($B10,CRV!$A:$A,CRV!$BY:$BY)+W11*XLOOKUP($B11,CRV!$A:$A,CRV!$BY:$BY),"ошибка")} -> 363 | AE11: При заказе
A12: Hydro-FS-A 1/1 CRV 10-18 G2-B-80-25 | B12: =IFERROR(__xludf.DUMMYFUNCTION("IFERROR(IF(REGEXMATCH(REGEXEXTRACT(A12,""\bCRV\s*\d+(?:-\d+)+(?:-(?:A?BI|AI|BI))?\b""),""-(?:A?BI|AI|BI)$""),REGEXREPLACE(REGEXEXTRACT(A12,""\bCRV\s*\d+(?:-\d+)+(?:-(?:A?BI|AI|BI))?\b""),""-(A?BI|AI|BI)$"",""C$1""),REGEXEXTRACT(A12,""\bCRV\s*\d+(?:-\d+)+("&"?:-(?:A?BI|AI|BI))?\b"")&""C""),"""")"),"CRV 10-18C") -> CRV 10-18C | C12: 1650 | D12: {=IFERROR(XLOOKUP($B12,CRV!$A:$A,CRV!$BA:$BA)+XLOOKUP($B12,CRV!$A:$A,CRV!$BB:$BB)+$O12,"")} -> 1384 | E12: 180 | F12: 565 | G12: 520 | H12: 1549 | I12: 1085 | J12: 1760 | K12: 427 | N12: 385 | O12: 100 | Q12: 12 отв. ø16 | R12: 1000 | S12: 800 | T12: 860 | U12: 450 | V12: =IFERROR(__xludf.DUMMYFUNCTION("IFERROR(REGEXEXTRACT(A12,""G2-B-(\d+)""),"""")"),"80") -> 80 | W12: =IF(OR(X12="", Y12=""), "", X12+Y12) -> 2 | X12: =IFERROR(__xludf.DUMMYFUNCTION("IFERROR(VALUE(REGEXEXTRACT(A12,""\b(\d+)/\d+\b"")),"""")"),1.0) -> 1 | Y12: =IFERROR(__xludf.DUMMYFUNCTION("IFERROR(VALUE(REGEXEXTRACT(A12,""\b\d+/(\d+)\b"")),"""") "),1.0) -> 1 | Z12: {=IFERROR(INDEX(CRV!BU:BU, MATCH(B12, CRV!A:A, 0)), "")} -> 7.5 | AA12: {=IFERROR(INDEX(CRV!BV:BV, MATCH(B12, CRV!A:A, 0))*X12+4.5*2+7, "")} -> 30.4 | AB12: {=IFERROR(IF(VALUE(XLOOKUP($B12,CRV!$A:$A,CRV!$BU:$BU))<=5.5,"прямой пуск (DOL)","звезда-треугольник (SD)"),"")} -> звезда-треугольник (SD) | AC12: {=IFERROR(INDEX(CRV!CA:CA, MATCH(B12, CRV!A:A, 0)), "")} -> HQQE | AD12: {=IFERROR(AD11-W12*XLOOKUP($B11,CRV!$A:$A,CRV!$BY:$BY)+W12*XLOOKUP($B12,CRV!$A:$A,CRV!$BY:$BY),"ошибка")} -> 373 | AE12: При заказе
A13: Hydro-FS-A 1/1 CRV 10-20 G2-B-80-25 | B13: =IFERROR(__xludf.DUMMYFUNCTION("IFERROR(IF(REGEXMATCH(REGEXEXTRACT(A13,""\bCRV\s*\d+(?:-\d+)+(?:-(?:A?BI|AI|BI))?\b""),""-(?:A?BI|AI|BI)$""),REGEXREPLACE(REGEXEXTRACT(A13,""\bCRV\s*\d+(?:-\d+)+(?:-(?:A?BI|AI|BI))?\b""),""-(A?BI|AI|BI)$"",""C$1""),REGEXEXTRACT(A13,""\bCRV\s*\d+(?:-\d+)+("&"?:-(?:A?BI|AI|BI))?\b"")&""C""),"""")"),"CRV 10-20C") -> CRV 10-20C | C13: 1650 | D13: {=IFERROR(XLOOKUP($B13,CRV!$A:$A,CRV!$BA:$BA)+XLOOKUP($B13,CRV!$A:$A,CRV!$BB:$BB)+$O13,"")} -> 1444 | E13: 180 | F13: 565 | G13: 520 | H13: 1549 | I13: 1085 | J13: 1760 | K13: 427 | N13: 385 | O13: 100 | Q13: 12 отв. ø16 | R13: 1000 | S13: 800 | T13: 860 | U13: 450 | V13: =IFERROR(__xludf.DUMMYFUNCTION("IFERROR(REGEXEXTRACT(A13,""G2-B-(\d+)""),"""")"),"80") -> 80 | W13: =IF(OR(X13="", Y13=""), "", X13+Y13) -> 2 | X13: =IFERROR(__xludf.DUMMYFUNCTION("IFERROR(VALUE(REGEXEXTRACT(A13,""\b(\d+)/\d+\b"")),"""")"),1.0) -> 1 | Y13: =IFERROR(__xludf.DUMMYFUNCTION("IFERROR(VALUE(REGEXEXTRACT(A13,""\b\d+/(\d+)\b"")),"""") "),1.0) -> 1 | Z13: {=IFERROR(INDEX(CRV!BU:BU, MATCH(B13, CRV!A:A, 0)), "")} -> 7.5 | AA13: {=IFERROR(INDEX(CRV!BV:BV, MATCH(B13, CRV!A:A, 0))*X13+4.5*2+7, "")} -> 30.4 | AB13: {=IFERROR(IF(VALUE(XLOOKUP($B13,CRV!$A:$A,CRV!$BU:$BU))<=5.5,"прямой пуск (DOL)","звезда-треугольник (SD)"),"")} -> звезда-треугольник (SD) | AC13: {=IFERROR(INDEX(CRV!CA:CA, MATCH(B13, CRV!A:A, 0)), "")} -> HQQE | AD13: {=IFERROR(AD12-W13*XLOOKUP($B12,CRV!$A:$A,CRV!$BY:$BY)+W13*XLOOKUP($B13,CRV!$A:$A,CRV!$BY:$BY),"ошибка")} -> 377 | AE13: При заказе
A14: Hydro-FS-A 1/1 CRV 10-22 G2-B-80-25 | B14: =IFERROR(__xludf.DUMMYFUNCTION("IFERROR(IF(REGEXMATCH(REGEXEXTRACT(A14,""\bCRV\s*\d+(?:-\d+)+(?:-(?:A?BI|AI|BI))?\b""),""-(?:A?BI|AI|BI)$""),REGEXREPLACE(REGEXEXTRACT(A14,""\bCRV\s*\d+(?:-\d+)+(?:-(?:A?BI|AI|BI))?\b""),""-(A?BI|AI|BI)$"",""C$1""),REGEXEXTRACT(A14,""\bCRV\s*\d+(?:-\d+)+("&"?:-(?:A?BI|AI|BI))?\b"")&""C""),"""")"),"CRV 10-22C") -> CRV 10-22C | C14: 1650 | D14: {=IFERROR(XLOOKUP($B14,CRV!$A:$A,CRV!$BA:$BA)+XLOOKUP($B14,CRV!$A:$A,CRV!$BB:$BB)+$O14,"")} -> 1504 | E14: 180 | F14: 565 | G14: 520 | H14: 1549 | I14: 1085 | J14: 1760 | K14: 427 | N14: 385 | O14: 100 | Q14: 12 отв. ø16 | R14: 1000 | S14: 800 | T14: 860 | U14: 450 | V14: =IFERROR(__xludf.DUMMYFUNCTION("IFERROR(REGEXEXTRACT(A14,""G2-B-(\d+)""),"""")"),"80") -> 80 | W14: =IF(OR(X14="", Y14=""), "", X14+Y14) -> 2 | X14: =IFERROR(__xludf.DUMMYFUNCTION("IFERROR(VALUE(REGEXEXTRACT(A14,""\b(\d+)/\d+\b"")),"""")"),1.0) -> 1 | Y14: =IFERROR(__xludf.DUMMYFUNCTION("IFERROR(VALUE(REGEXEXTRACT(A14,""\b\d+/(\d+)\b"")),"""") "),1.0) -> 1 | Z14: {=IFERROR(INDEX(CRV!BU:BU, MATCH(B14, CRV!A:A, 0)), "")} -> 7.5 | AA14: {=IFERROR(INDEX(CRV!BV:BV, MATCH(B14, CRV!A:A, 0))*X14+4.5*2+7, "")} -> 30.4 | AB14: {=IFERROR(IF(VALUE(XLOOKUP($B14,CRV!$A:$A,CRV!$BU:$BU))<=5.5,"прямой пуск (DOL)","звезда-треугольник (SD)"),"")} -> звезда-треугольник (SD) | AC14: {=IFERROR(INDEX(CRV!CA:CA, MATCH(B14, CRV!A:A, 0)), "")} -> HQQE | AD14: {=IFERROR(AD13-W14*XLOOKUP($B13,CRV!$A:$A,CRV!$BY:$BY)+W14*XLOOKUP($B14,CRV!$A:$A,CRV!$BY:$BY),"ошибка")} -> 383 | AE14: При заказе
B15: =IFERROR(__xludf.DUMMYFUNCTION("IFERROR(IF(REGEXMATCH(REGEXEXTRACT(A15,""\bCRV\s*\d+(?:-\d+)+(?:-(?:A?BI|AI|BI))?\b""),""-(?:A?BI|AI|BI)$""),REGEXREPLACE(REGEXEXTRACT(A15,""\bCRV\s*\d+(?:-\d+)+(?:-(?:A?BI|AI|BI))?\b""),""-(A?BI|AI|BI)$"",""C$1""),REGEXEXTRACT(A15,""\bCRV\s*\d+(?:-\d+)+("&"?:-(?:A?BI|AI|BI))?\b"")&""C""),"""")"),"") | D15: {=IFERROR(XLOOKUP($B15,CRV!$A:$A,CRV!$BA:$BA)+XLOOKUP($B15,CRV!$A:$A,CRV!$BB:$BB)+$O15,"")} | V15: =IFERROR(__xludf.DUMMYFUNCTION("IFERROR(REGEXEXTRACT(A15,""G2-B-(\d+)""),"""")"),"") | W15: =IF(OR(X15="", Y15=""), "", X15+Y15) | X15: =IFERROR(__xludf.DUMMYFUNCTION("IFERROR(VALUE(REGEXEXTRACT(A15,""\b(\d+)/\d+\b"")),"""")"),"") | Y15: =IFERROR(__xludf.DUMMYFUNCTION("IFERROR(VALUE(REGEXEXTRACT(A15,""\b\d+/(\d+)\b"")),"""") "),"") | Z15: {=IFERROR(INDEX(CRV!BU:BU, MATCH(B15, CRV!A:A, 0)), "")} | AA15: {=IFERROR(INDEX(CRV!BV:BV, MATCH(B15, CRV!A:A, 0))*X15+4.5*2+7, "")} | AB15: {=IFERROR(IF(VALUE(XLOOKUP($B15,CRV!$A:$A,CRV!$BU:$BU))<=5.5,"прямой пуск (DOL)","звезда-треугольник (SD)"),"")} | AC15: {=IFERROR(INDEX(CRV!CA:CA, MATCH(B15, CRV!A:A, 0)), "")}
A16: Hydro-FS-A 1/1 CRV 15-1 G2-B-80-16 | B16: =IFERROR(__xludf.DUMMYFUNCTION("IFERROR(IF(REGEXMATCH(REGEXEXTRACT(A16,""\bCRV\s*\d+(?:-\d+)+(?:-(?:A?BI|AI|BI))?\b""),""-(?:A?BI|AI|BI)$""),REGEXREPLACE(REGEXEXTRACT(A16,""\bCRV\s*\d+(?:-\d+)+(?:-(?:A?BI|AI|BI))?\b""),""-(A?BI|AI|BI)$"",""C$1""),REGEXEXTRACT(A16,""\bCRV\s*\d+(?:-\d+)+("&"?:-(?:A?BI|AI|BI))?\b"")&""C""),"""")"),"CRV 15-1C") -> CRV 15-1C | C16: 1650 | D16: {=IFERROR(XLOOKUP($B16,CRV!$A:$A,CRV!$BA:$BA)+XLOOKUP($B16,CRV!$A:$A,CRV!$BB:$BB)+$O16,"")} -> 672 | E16: 190 | F16: 585 | G16: 540 | H16: 1589 | I16: 1125 | J16: 1760 | K16: 427 | N16: 385 | O16: 100 | Q16: 12 отв. ø16 | R16: 1000 | S16: 800 | T16: 860 | U16: 450 | V16: =IFERROR(__xludf.DUMMYFUNCTION("IFERROR(REGEXEXTRACT(A16,""G2-B-(\d+)""),"""")"),"80") -> 80 | W16: =IF(OR(X16="", Y16=""), "", X16+Y16) -> 2 | X16: =IFERROR(__xludf.DUMMYFUNCTION("IFERROR(VALUE(REGEXEXTRACT(A16,""\b(\d+)/\d+\b"")),"""")"),1.0) -> 1 | Y16: =IFERROR(__xludf.DUMMYFUNCTION("IFERROR(VALUE(REGEXEXTRACT(A16,""\b\d+/(\d+)\b"")),"""") "),1.0) -> 1 | Z16: {=IFERROR(INDEX(CRV!BU:BU, MATCH(B16, CRV!A:A, 0)), "")} -> 1.1 | AA16: {=IFERROR(INDEX(CRV!BV:BV, MATCH(B16, CRV!A:A, 0))*X16+4.5*2+7, "")} -> 20.2 | AB16: {=IFERROR(IF(VALUE(XLOOKUP($B16,CRV!$A:$A,CRV!$BU:$BU))<=5.5,"прямой пуск (DOL)","звезда-треугольник (SD)"),"")} -> прямой пуск (DOL) | AC16: {=IFERROR(INDEX(CRV!CA:CA, MATCH(B16, CRV!A:A, 0)), "")} -> HQQE | AD16: 267 | AE16: 75211375
A17: Hydro-FS-A 1/1 CRV 15-2 G2-B-80-16 | B17: =IFERROR(__xludf.DUMMYFUNCTION("IFERROR(IF(REGEXMATCH(REGEXEXTRACT(A17,""\bCRV\s*\d+(?:-\d+)+(?:-(?:A?BI|AI|BI))?\b""),""-(?:A?BI|AI|BI)$""),REGEXREPLACE(REGEXEXTRACT(A17,""\bCRV\s*\d+(?:-\d+)+(?:-(?:A?BI|AI|BI))?\b""),""-(A?BI|AI|BI)$"",""C$1""),REGEXEXTRACT(A17,""\bCRV\s*\d+(?:-\d+)+("&"?:-(?:A?BI|AI|BI))?\b"")&""C""),"""")"),"CRV 15-2C") -> CRV 15-2C | C17: 1650 | D17: {=IFERROR(XLOOKUP($B17,CRV!$A:$A,CRV!$BA:$BA)+XLOOKUP($B17,CRV!$A:$A,CRV!$BB:$BB)+$O17,"")} -> 769 | E17: 190 | F17: 585 | G17: 540 | H17: 1589 | I17: 1125 | J17: 1760 | K17: 427 | N17: 385 | O17: 100 | Q17: 12 отв. ø16 | R17: 1000 | S17: 800 | T17: 860 | U17: 450 | V17: =IFERROR(__xludf.DUMMYFUNCTION("IFERROR(REGEXEXTRACT(A17,""G2-B-(\d+)""),"""")"),"80") -> 80 | W17: =IF(OR(X17="", Y17=""), "", X17+Y17) -> 2 | X17: =IFERROR(__xludf.DUMMYFUNCTION("IFERROR(VALUE(REGEXEXTRACT(A17,""\b(\d+)/\d+\b"")),"""")"),1.0) -> 1 | Y17: =IFERROR(__xludf.DUMMYFUNCTION("IFERROR(VALUE(REGEXEXTRACT(A17,""\b\d+/(\d+)\b"")),"""") "),1.0) -> 1 | Z17: {=IFERROR(INDEX(CRV!BU:BU, MATCH(B17, CRV!A:A, 0)), "")} -> 2.2 | AA17: {=IFERROR(INDEX(CRV!BV:BV, MATCH(B17, CRV!A:A, 0))*X17+4.5*2+7, "")} -> 23.9 | AB17: {=IFERROR(IF(VALUE(XLOOKUP($B17,CRV!$A:$A,CRV!$BU:$BU))<=5.5,"прямой пуск (DOL)","звезда-треугольник (SD)"),"")} -> прямой пуск (DOL) | AC17: {=IFERROR(INDEX(CRV!CA:CA, MATCH(B17, CRV!A:A, 0)), "")} -> HQQE | AD17: 283 | AE17: 75211392
A18: Hydro-FS-A 1/1 CRV 15-3 G2-B-80-16 | B18: =IFERROR(__xludf.DUMMYFUNCTION("IFERROR(IF(REGEXMATCH(REGEXEXTRACT(A18,""\bCRV\s*\d+(?:-\d+)+(?:-(?:A?BI|AI|BI))?\b""),""-(?:A?BI|AI|BI)$""),REGEXREPLACE(REGEXEXTRACT(A18,""\bCRV\s*\d+(?:-\d+)+(?:-(?:A?BI|AI|BI))?\b""),""-(A?BI|AI|BI)$"",""C$1""),REGEXEXTRACT(A18,""\bCRV\s*\d+(?:-\d+)+("&"?:-(?:A?BI|AI|BI))?\b"")&""C""),"""")"),"CRV 15-3C") -> CRV 15-3C | C18: 1650 | D18: {=IFERROR(XLOOKUP($B18,CRV!$A:$A,CRV!$BA:$BA)+XLOOKUP($B18,CRV!$A:$A,CRV!$BB:$BB)+$O18,"")} -> 834 | E18: 190 | F18: 585 | G18: 540 | H18: 1589 | I18: 1125 | J18: 1760 | K18: 427 | N18: 385 | O18: 100 | Q18: 12 отв. ø16 | R18: 1000 | S18: 800 | T18: 860 | U18: 450 | V18: =IFERROR(__xludf.DUMMYFUNCTION("IFERROR(REGEXEXTRACT(A18,""G2-B-(\d+)""),"""")"),"80") -> 80 | W18: =IF(OR(X18="", Y18=""), "", X18+Y18) -> 2 | X18: =IFERROR(__xludf.DUMMYFUNCTION("IFERROR(VALUE(REGEXEXTRACT(A18,""\b(\d+)/\d+\b"")),"""")"),1.0) -> 1 | Y18: =IFERROR(__xludf.DUMMYFUNCTION("IFERROR(VALUE(REGEXEXTRACT(A18,""\b\d+/(\d+)\b"")),"""") "),1.0) -> 1 | Z18: {=IFERROR(INDEX(CRV!BU:BU, MATCH(B18, CRV!A:A, 0)), "")} -> 3 | AA18: {=IFERROR(INDEX(CRV!BV:BV, MATCH(B18, CRV!A:A, 0))*X18+4.5*2+7, "")} -> 26.4 | AB18: {=IFERROR(IF(VALUE(XLOOKUP($B18,CRV!$A:$A,CRV!$BU:$BU))<=5.5,"прямой пуск (DOL)","звезда-треугольник (SD)"),"")} -> прямой пуск (DOL) | AC18: {=IFERROR(INDEX(CRV!CA:CA, MATCH(B18, CRV!A:A, 0)), "")} -> HQQE | AD18: 293 | AE18: 75211393
A19: Hydro-FS-A 1/1 CRV 15-4 G2-B-80-16 | B19: =IFERROR(__xludf.DUMMYFUNCTION("IFERROR(IF(REGEXMATCH(REGEXEXTRACT(A19,""\bCRV\s*\d+(?:-\d+)+(?:-(?:A?BI|AI|BI))?\b""),""-(?:A?BI|AI|BI)$""),REGEXREPLACE(REGEXEXTRACT(A19,""\bCRV\s*\d+(?:-\d+)+(?:-(?:A?BI|AI|BI))?\b""),""-(A?BI|AI|BI)$"",""C$1""),REGEXEXTRACT(A19,""\bCRV\s*\d+(?:-\d+)+("&"?:-(?:A?BI|AI|BI))?\b"")&""C""),"""")"),"CRV 15-4C") -> CRV 15-4C | C19: 1650 | D19: {=IFERROR(XLOOKUP($B19,CRV!$A:$A,CRV!$BA:$BA)+XLOOKUP($B19,CRV!$A:$A,CRV!$BB:$BB)+$O19,"")} -> 912 | E19: 190 | F19: 585 | G19: 540 | H19: 1589 | I19: 1125 | J19: 1760 | K19: 427 | N19: 385 | O19: 100 | Q19: 12 отв. ø16 | R19: 1000 | S19: 800 | T19: 860 | U19: 450 | V19: =IFERROR(__xludf.DUMMYFUNCTION("IFERROR(REGEXEXTRACT(A19,""G2-B-(\d+)""),"""")"),"80") -> 80 | W19: =IF(OR(X19="", Y19=""), "", X19+Y19) -> 2 | X19: =IFERROR(__xludf.DUMMYFUNCTION("IFERROR(VALUE(REGEXEXTRACT(A19,""\b(\d+)/\d+\b"")),"""")"),1.0) -> 1 | Y19: =IFERROR(__xludf.DUMMYFUNCTION("IFERROR(VALUE(REGEXEXTRACT(A19,""\b\d+/(\d+)\b"")),"""") "),1.0) -> 1 | Z19: {=IFERROR(INDEX(CRV!BU:BU, MATCH(B19, CRV!A:A, 0)), "")} -> 4 | AA19: {=IFERROR(INDEX(CRV!BV:BV, MATCH(B19, CRV!A:A, 0))*X19+4.5*2+7, "")} -> 23.8 | AB19: {=IFERROR(IF(VALUE(XLOOKUP($B19,CRV!$A:$A,CRV!$BU:$BU))<=5.5,"прямой пуск (DOL)","звезда-треугольник (SD)"),"")} -> прямой пуск (DOL) | AC19: {=IFERROR(INDEX(CRV!CA:CA, MATCH(B19, CRV!A:A, 0)), "")} -> HQQE | AD19: 319 | AE19: 75211394
A20: Hydro-FS-A 1/1 CRV 15-5 G2-B-80-16 | B20: =IFERROR(__xludf.DUMMYFUNCTION("IFERROR(IF(REGEXMATCH(REGEXEXTRACT(A20,""\bCRV\s*\d+(?:-\d+)+(?:-(?:A?BI|AI|BI))?\b""),""-(?:A?BI|AI|BI)$""),REGEXREPLACE(REGEXEXTRACT(A20,""\bCRV\s*\d+(?:-\d+)+(?:-(?:A?BI|AI|BI))?\b""),""-(A?BI|AI|BI)$"",""C$1""),REGEXEXTRACT(A20,""\bCRV\s*\d+(?:-\d+)+("&"?:-(?:A?BI|AI|BI))?\b"")&""C""),"""")"),"CRV 15-5C") -> CRV 15-5C | C20: 1650 | D20: {=IFERROR(XLOOKUP($B20,CRV!$A:$A,CRV!$BA:$BA)+XLOOKUP($B20,CRV!$A:$A,CRV!$BB:$BB)+$O20,"")} -> 957 | E20: 190 | F20: 585 | G20: 540 | H20: 1589 | I20: 1125 | J20: 1760 | K20: 427 | N20: 385 | O20: 100 | Q20: 12 отв. ø16 | R20: 1000 | S20: 800 | T20: 860 | U20: 450 | V20: =IFERROR(__xludf.DUMMYFUNCTION("IFERROR(REGEXEXTRACT(A20,""G2-B-(\d+)""),"""")"),"80") -> 80 | W20: =IF(OR(X20="", Y20=""), "", X20+Y20) -> 2 | X20: =IFERROR(__xludf.DUMMYFUNCTION("IFERROR(VALUE(REGEXEXTRACT(A20,""\b(\d+)/\d+\b"")),"""")"),1.0) -> 1 | Y20: =IFERROR(__xludf.DUMMYFUNCTION("IFERROR(VALUE(REGEXEXTRACT(A20,""\b\d+/(\d+)\b"")),"""") "),1.0) -> 1 | Z20: {=IFERROR(INDEX(CRV!BU:BU, MATCH(B20, CRV!A:A, 0)), "")} -> 4 | AA20: {=IFERROR(INDEX(CRV!BV:BV, MATCH(B20, CRV!A:A, 0))*X20+4.5*2+7, "")} -> 23.8 | AB20: {=IFERROR(IF(VALUE(XLOOKUP($B20,CRV!$A:$A,CRV!$BU:$BU))<=5.5,"прямой пуск (DOL)","звезда-треугольник (SD)"),"")} -> прямой пуск (DOL) | AC20: {=IFERROR(INDEX(CRV!CA:CA, MATCH(B20, CRV!A:A, 0)), "")} -> HQQE | AD20: 321 | AE20: 75211395
A21: Hydro-FS-A 1/1 CRV 15-6 G2-B-80-16 | B21: =IFERROR(__xludf.DUMMYFUNCTION("IFERROR(IF(REGEXMATCH(REGEXEXTRACT(A21,""\bCRV\s*\d+(?:-\d+)+(?:-(?:A?BI|AI|BI))?\b""),""-(?:A?BI|AI|BI)$""),REGEXREPLACE(REGEXEXTRACT(A21,""\bCRV\s*\d+(?:-\d+)+(?:-(?:A?BI|AI|BI))?\b""),""-(A?BI|AI|BI)$"",""C$1""),REGEXEXTRACT(A21,""\bCRV\s*\d+(?:-\d+)+("&"?:-(?:A?BI|AI|BI))?\b"")&""C""),"""")"),"CRV 15-6C") -> CRV 15-6C | C21: 1650 | D21: {=IFERROR(XLOOKUP($B21,CRV!$A:$A,CRV!$BA:$BA)+XLOOKUP($B21,CRV!$A:$A,CRV!$BB:$BB)+$O21,"")} -> 1083 | E21: 190 | F21: 585 | G21: 540 | H21: 1589 | I21: 1125 | J21: 1760 | K21: 427 | N21: 385 | O21: 100 | Q21: 12 отв. ø16 | R21: 1000 | S21: 800 | T21: 860 | U21: 450 | V21: =IFERROR(__xludf.DUMMYFUNCTION("IFERROR(REGEXEXTRACT(A21,""G2-B-(\d+)""),"""")"),"80") -> 80 | W21: =IF(OR(X21="", Y21=""), "", X21+Y21) -> 2 | X21: =IFERROR(__xludf.DUMMYFUNCTION("IFERROR(VALUE(REGEXEXTRACT(A21,""\b(\d+)/\d+\b"")),"""")"),1.0) -> 1 | Y21: =IFERROR(__xludf.DUMMYFUNCTION("IFERROR(VALUE(REGEXEXTRACT(A21,""\b\d+/(\d+)\b"")),"""") "),1.0) -> 1 | Z21: {=IFERROR(INDEX(CRV!BU:BU, MATCH(B21, CRV!A:A, 0)), "")} -> 5.5 | AA21: {=IFERROR(INDEX(CRV!BV:BV, MATCH(B21, CRV!A:A, 0))*X21+4.5*2+7, "")} -> 26.6 | AB21: {=IFERROR(IF(VALUE(XLOOKUP($B21,CRV!$A:$A,CRV!$BU:$BU))<=5.5,"прямой пуск (DOL)","звезда-треугольник (SD)"),"")} -> прямой пуск (DOL) | AC21: {=IFERROR(INDEX(CRV!CA:CA, MATCH(B21, CRV!A:A, 0)), "")} -> HQQE | AD21: 365 | AE21: 75211396
A22: Hydro-FS-A 1/1 CRV 15-7 G2-B-80-16 | B22: =IFERROR(__xludf.DUMMYFUNCTION("IFERROR(IF(REGEXMATCH(REGEXEXTRACT(A22,""\bCRV\s*\d+(?:-\d+)+(?:-(?:A?BI|AI|BI))?\b""),""-(?:A?BI|AI|BI)$""),REGEXREPLACE(REGEXEXTRACT(A22,""\bCRV\s*\d+(?:-\d+)+(?:-(?:A?BI|AI|BI))?\b""),""-(A?BI|AI|BI)$"",""C$1""),REGEXEXTRACT(A22,""\bCRV\s*\d+(?:-\d+)+("&"?:-(?:A?BI|AI|BI))?\b"")&""C""),"""")"),"CRV 15-7C") -> CRV 15-7C | C22: 1650 | D22: {=IFERROR(XLOOKUP($B22,CRV!$A:$A,CRV!$BA:$BA)+XLOOKUP($B22,CRV!$A:$A,CRV!$BB:$BB)+$O22,"")} -> 1128 | E22: 190 | F22: 585 | G22: 540 | H22: 1589 | I22: 1125 | J22: 1760 | K22: 427 | N22: 385 | O22: 100 | Q22: 12 отв. ø16 | R22: 1000 | S22: 800 | T22: 860 | U22: 450 | V22: =IFERROR(__xludf.DUMMYFUNCTION("IFERROR(REGEXEXTRACT(A22,""G2-B-(\d+)""),"""")"),"80") -> 80 | W22: =IF(OR(X22="", Y22=""), "", X22+Y22) -> 2 | X22: =IFERROR(__xludf.DUMMYFUNCTION("IFERROR(VALUE(REGEXEXTRACT(A22,""\b(\d+)/\d+\b"")),"""")"),1.0) -> 1 | Y22: =IFERROR(__xludf.DUMMYFUNCTION("IFERROR(VALUE(REGEXEXTRACT(A22,""\b\d+/(\d+)\b"")),"""") "),1.0) -> 1 | Z22: {=IFERROR(INDEX(CRV!BU:BU, MATCH(B22, CRV!A:A, 0)), "")} -> 5.5 | AA22: {=IFERROR(INDEX(CRV!BV:BV, MATCH(B22, CRV!A:A, 0))*X22+4.5*2+7, "")} -> 26.6 | AB22: {=IFERROR(IF(VALUE(XLOOKUP($B22,CRV!$A:$A,CRV!$BU:$BU))<=5.5,"прямой пуск (DOL)","звезда-треугольник (SD)"),"")} -> прямой пуск (DOL) | AC22: {=IFERROR(INDEX(CRV!CA:CA, MATCH(B22, CRV!A:A, 0)), "")} -> HQQE | AD22: 369 | AE22: 75211397
A23: Hydro-FS-A 1/1 CRV 15-8 G2-B-80-16 | B23: =IFERROR(__xludf.DUMMYFUNCTION("IFERROR(IF(REGEXMATCH(REGEXEXTRACT(A23,""\bCRV\s*\d+(?:-\d+)+(?:-(?:A?BI|AI|BI))?\b""),""-(?:A?BI|AI|BI)$""),REGEXREPLACE(REGEXEXTRACT(A23,""\bCRV\s*\d+(?:-\d+)+(?:-(?:A?BI|AI|BI))?\b""),""-(A?BI|AI|BI)$"",""C$1""),REGEXEXTRACT(A23,""\bCRV\s*\d+(?:-\d+)+("&"?:-(?:A?BI|AI|BI))?\b"")&""C""),"""")"),"CRV 15-8C") -> CRV 15-8C | C23: 1650 | D23: {=IFERROR(XLOOKUP($B23,CRV!$A:$A,CRV!$BA:$BA)+XLOOKUP($B23,CRV!$A:$A,CRV!$BB:$BB)+$O23,"")} -> 1211 | E23: 190 | F23: 585 | G23: 540 | H23: 1589 | I23: 1125 | J23: 1760 | K23: 427 | N23: 385 | O23: 100 | Q23: 12 отв. ø16 | R23: 1000 | S23: 800 | T23: 860 | U23: 450 | V23: =IFERROR(__xludf.DUMMYFUNCTION("IFERROR(REGEXEXTRACT(A23,""G2-B-(\d+)""),"""")"),"80") -> 80 | W23: =IF(OR(X23="", Y23=""), "", X23+Y23) -> 2 | X23: =IFERROR(__xludf.DUMMYFUNCTION("IFERROR(VALUE(REGEXEXTRACT(A23,""\b(\d+)/\d+\b"")),"""")"),1.0) -> 1 | Y23: =IFERROR(__xludf.DUMMYFUNCTION("IFERROR(VALUE(REGEXEXTRACT(A23,""\b\d+/(\d+)\b"")),"""") "),1.0) -> 1 | Z23: {=IFERROR(INDEX(CRV!BU:BU, MATCH(B23, CRV!A:A, 0)), "")} -> 7.5 | AA23: {=IFERROR(INDEX(CRV!BV:BV, MATCH(B23, CRV!A:A, 0))*X23+4.5*2+7, "")} -> 30.4 | AB23: {=IFERROR(IF(VALUE(XLOOKUP($B23,CRV!$A:$A,CRV!$BU:$BU))<=5.5,"прямой пуск (DOL)","звезда-треугольник (SD)"),"")} -> звезда-треугольник (SD) | AC23: {=IFERROR(INDEX(CRV!CA:CA, MATCH(B23, CRV!A:A, 0)), "")} -> HQQE | AD23: 377 | AE23: 75211398
A24: Hydro-FS-A 1/1 CRV 15-9 G2-B-80-16 | B24: =IFERROR(__xludf.DUMMYFUNCTION("IFERROR(IF(REGEXMATCH(REGEXEXTRACT(A24,""\bCRV\s*\d+(?:-\d+)+(?:-(?:A?BI|AI|BI))?\b""),""-(?:A?BI|AI|BI)$""),REGEXREPLACE(REGEXEXTRACT(A24,""\bCRV\s*\d+(?:-\d+)+(?:-(?:A?BI|AI|BI))?\b""),""-(A?BI|AI|BI)$"",""C$1""),REGEXEXTRACT(A24,""\bCRV\s*\d+(?:-\d+)+("&"?:-(?:A?BI|AI|BI))?\b"")&""C""),"""")"),"CRV 15-9C") -> CRV 15-9C | C24: 1650 | D24: {=IFERROR(XLOOKUP($B24,CRV!$A:$A,CRV!$BA:$BA)+XLOOKUP($B24,CRV!$A:$A,CRV!$BB:$BB)+$O24,"")} -> 1256 | E24: 190 | F24: 585 | G24: 540 | H24: 1589 | I24: 1125 | J24: 1760 | K24: 427 | N24: 385 | O24: 100 | Q24: 12 отв. ø16 | R24: 1000 | S24: 800 | T24: 860 | U24: 450 | V24: =IFERROR(__xludf.DUMMYFUNCTION("IFERROR(REGEXEXTRACT(A24,""G2-B-(\d+)""),"""")"),"80") -> 80 | W24: =IF(OR(X24="", Y24=""), "", X24+Y24) -> 2 | X24: =IFERROR(__xludf.DUMMYFUNCTION("IFERROR(VALUE(REGEXEXTRACT(A24,""\b(\d+)/\d+\b"")),"""")"),1.0) -> 1 | Y24: =IFERROR(__xludf.DUMMYFUNCTION("IFERROR(VALUE(REGEXEXTRACT(A24,""\b\d+/(\d+)\b"")),"""") "),1.0) -> 1 | Z24: {=IFERROR(INDEX(CRV!BU:BU, MATCH(B24, CRV!A:A, 0)), "")} -> 7.5 | AA24: {=IFERROR(INDEX(CRV!BV:BV, MATCH(B24, CRV!A:A, 0))*X24+4.5*2+7, "")} -> 30.4 | AB24: {=IFERROR(IF(VALUE(XLOOKUP($B24,CRV!$A:$A,CRV!$BU:$BU))<=5.5,"прямой пуск (DOL)","звезда-треугольник (SD)"),"")} -> звезда-треугольник (SD) | AC24: {=IFERROR(INDEX(CRV!CA:CA, MATCH(B24, CRV!A:A, 0)), "")} -> HQQE | AD24: 379 | AE24: 75211399
A25: Hydro-FS-A 1/1 CRV 15-10 G2-B-80-16 | B25: =IFERROR(__xludf.DUMMYFUNCTION("IFERROR(IF(REGEXMATCH(REGEXEXTRACT(A25,""\bCRV\s*\d+(?:-\d+)+(?:-(?:A?BI|AI|BI))?\b""),""-(?:A?BI|AI|BI)$""),REGEXREPLACE(REGEXEXTRACT(A25,""\bCRV\s*\d+(?:-\d+)+(?:-(?:A?BI|AI|BI))?\b""),""-(A?BI|AI|BI)$"",""C$1""),REGEXEXTRACT(A25,""\bCRV\s*\d+(?:-\d+)+("&"?:-(?:A?BI|AI|BI))?\b"")&""C""),"""")"),"CRV 15-10C") -> CRV 15-10C | C25: 1650 | D25: {=IFERROR(XLOOKUP($B25,CRV!$A:$A,CRV!$BA:$BA)+XLOOKUP($B25,CRV!$A:$A,CRV!$BB:$BB)+$O25,"")} -> 1417 | E25: 190 | F25: 585 | G25: 540 | H25: 1589 | I25: 1125 | J25: 1760 | K25: 427 | N25: 385 | O25: 100 | Q25: 12 отв. ø16 | R25: 1000 | S25: 800 | T25: 860 | U25: 450 | V25: =IFERROR(__xludf.DUMMYFUNCTION("IFERROR(REGEXEXTRACT(A25,""G2-B-(\d+)""),"""")"),"80") -> 80 | W25: =IF(OR(X25="", Y25=""), "", X25+Y25) -> 2 | X25: =IFERROR(__xludf.DUMMYFUNCTION("IFERROR(VALUE(REGEXEXTRACT(A25,""\b(\d+)/\d+\b"")),"""")"),1.0) -> 1 | Y25: =IFERROR(__xludf.DUMMYFUNCTION("IFERROR(VALUE(REGEXEXTRACT(A25,""\b\d+/(\d+)\b"")),"""") "),1.0) -> 1 | Z25: {=IFERROR(INDEX(CRV!BU:BU, MATCH(B25, CRV!A:A, 0)), "")} -> 11 | AA25: {=IFERROR(INDEX(CRV!BV:BV, MATCH(B25, CRV!A:A, 0))*X25+4.5*2+7, "")} -> 36.6 | AB25: {=IFERROR(IF(VALUE(XLOOKUP($B25,CRV!$A:$A,CRV!$BU:$BU))<=5.5,"прямой пуск (DOL)","звезда-треугольник (SD)"),"")} -> звезда-треугольник (SD) | AC25: {=IFERROR(INDEX(CRV!CA:CA, MATCH(B25, CRV!A:A, 0)), "")} -> HQQE | AD25: 465 | AE25: 75211400
A26: Hydro-FS-A 1/1 CRV 15-12 G2-B-80-25 | B26: =IFERROR(__xludf.DUMMYFUNCTION("IFERROR(IF(REGEXMATCH(REGEXEXTRACT(A26,""\bCRV\s*\d+(?:-\d+)+(?:-(?:A?BI|AI|BI))?\b""),""-(?:A?BI|AI|BI)$""),REGEXREPLACE(REGEXEXTRACT(A26,""\bCRV\s*\d+(?:-\d+)+(?:-(?:A?BI|AI|BI))?\b""),""-(A?BI|AI|BI)$"",""C$1""),REGEXEXTRACT(A26,""\bCRV\s*\d+(?:-\d+)+("&"?:-(?:A?BI|AI|BI))?\b"")&""C""),"""")"),"CRV 15-12C") -> CRV 15-12C | C26: 1650 | D26: {=IFERROR(XLOOKUP($B26,CRV!$A:$A,CRV!$BA:$BA)+XLOOKUP($B26,CRV!$A:$A,CRV!$BB:$BB)+$O26,"")} -> 1507 | E26: 190 | F26: 585 | G26: 540 | H26: 1589 | I26: 1125 | J26: 1760 | K26: 427 | N26: 385 | O26: 100 | Q26: 12 отв. ø16 | R26: 1000 | S26: 800 | T26: 860 | U26: 450 | V26: =IFERROR(__xludf.DUMMYFUNCTION("IFERROR(REGEXEXTRACT(A26,""G2-B-(\d+)""),"""")"),"80") -> 80 | W26: =IF(OR(X26="", Y26=""), "", X26+Y26) -> 2 | X26: =IFERROR(__xludf.DUMMYFUNCTION("IFERROR(VALUE(REGEXEXTRACT(A26,""\b(\d+)/\d+\b"")),"""")"),1.0) -> 1 | Y26: =IFERROR(__xludf.DUMMYFUNCTION("IFERROR(VALUE(REGEXEXTRACT(A26,""\b\d+/(\d+)\b"")),"""") "),1.0) -> 1 | Z26: {=IFERROR(INDEX(CRV!BU:BU, MATCH(B26, CRV!A:A, 0)), "")} -> 11 | AA26: {=IFERROR(INDEX(CRV!BV:BV, MATCH(B26, CRV!A:A, 0))*X26+4.5*2+7, "")} -> 36.6 | AB26: {=IFERROR(IF(VALUE(XLOOKUP($B26,CRV!$A:$A,CRV!$BU:$BU))<=5.5,"прямой пуск (DOL)","звезда-треугольник (SD)"),"")} -> звезда-треугольник (SD) | AC26: {=IFERROR(INDEX(CRV!CA:CA, MATCH(B26, CRV!A:A, 0)), "")} -> HQQE | AD26: {=IFERROR(AD25-W26*XLOOKUP($B25,CRV!$A:$A,CRV!$BY:$BY)+W26*XLOOKUP($B26,CRV!$A:$A,CRV!$BY:$BY),"ошибка")} -> 473 | AE26: При заказе
A27: Hydro-FS-A 1/1 CRV 15-14 G2-B-80-25 | B27: =IFERROR(__xludf.DUMMYFUNCTION("IFERROR(IF(REGEXMATCH(REGEXEXTRACT(A27,""\bCRV\s*\d+(?:-\d+)+(?:-(?:A?BI|AI|BI))?\b""),""-(?:A?BI|AI|BI)$""),REGEXREPLACE(REGEXEXTRACT(A27,""\bCRV\s*\d+(?:-\d+)+(?:-(?:A?BI|AI|BI))?\b""),""-(A?BI|AI|BI)$"",""C$1""),REGEXEXTRACT(A27,""\bCRV\s*\d+(?:-\d+)+("&"?:-(?:A?BI|AI|BI))?\b"")&""C""),"""")"),"CRV 15-14C") -> CRV 15-14C | C27: 1650 | D27: {=IFERROR(XLOOKUP($B27,CRV!$A:$A,CRV!$BA:$BA)+XLOOKUP($B27,CRV!$A:$A,CRV!$BB:$BB)+$O27,"")} -> 1597 | E27: 190 | F27: 585 | G27: 540 | H27: 1589 | I27: 1125 | J27: 1760 | K27: 427 | N27: 385 | O27: 100 | Q27: 12 отв. ø16 | R27: 1000 | S27: 800 | T27: 860 | U27: 450 | V27: =IFERROR(__xludf.DUMMYFUNCTION("IFERROR(REGEXEXTRACT(A27,""G2-B-(\d+)""),"""")"),"80") -> 80 | W27: =IF(OR(X27="", Y27=""), "", X27+Y27) -> 2 | X27: =IFERROR(__xludf.DUMMYFUNCTION("IFERROR(VALUE(REGEXEXTRACT(A27,""\b(\d+)/\d+\b"")),"""")"),1.0) -> 1 | Y27: =IFERROR(__xludf.DUMMYFUNCTION("IFERROR(VALUE(REGEXEXTRACT(A27,""\b\d+/(\d+)\b"")),"""") "),1.0) -> 1 | Z27: {=IFERROR(INDEX(CRV!BU:BU, MATCH(B27, CRV!A:A, 0)), "")} -> 11 | AA27: {=IFERROR(INDEX(CRV!BV:BV, MATCH(B27, CRV!A:A, 0))*X27+4.5*2+7, "")} -> 36.6 | AB27: {=IFERROR(IF(VALUE(XLOOKUP($B27,CRV!$A:$A,CRV!$BU:$BU))<=5.5,"прямой пуск (DOL)","звезда-треугольник (SD)"),"")} -> звезда-треугольник (SD) | AC27: {=IFERROR(INDEX(CRV!CA:CA, MATCH(B27, CRV!A:A, 0)), "")} -> HQQE | AD27: {=IFERROR(AD26-W27*XLOOKUP($B26,CRV!$A:$A,CRV!$BY:$BY)+W27*XLOOKUP($B27,CRV!$A:$A,CRV!$BY:$BY),"ошибка")} -> 479 | AE27: При заказе
A28: Hydro-FS-A 1/1 CRV 15-17 G2-B-80-25 | B28: =IFERROR(__xludf.DUMMYFUNCTION("IFERROR(IF(REGEXMATCH(REGEXEXTRACT(A28,""\bCRV\s*\d+(?:-\d+)+(?:-(?:A?BI|AI|BI))?\b""),""-(?:A?BI|AI|BI)$""),REGEXREPLACE(REGEXEXTRACT(A28,""\bCRV\s*\d+(?:-\d+)+(?:-(?:A?BI|AI|BI))?\b""),""-(A?BI|AI|BI)$"",""C$1""),REGEXEXTRACT(A28,""\bCRV\s*\d+(?:-\d+)+("&"?:-(?:A?BI|AI|BI))?\b"")&""C""),"""")"),"CRV 15-17C") -> CRV 15-17C | C28: 1650 | D28: {=IFERROR(XLOOKUP($B28,CRV!$A:$A,CRV!$BA:$BA)+XLOOKUP($B28,CRV!$A:$A,CRV!$BB:$BB)+$O28,"")} -> 1773 | E28: 190 | F28: 585 | G28: 540 | H28: 1589 | I28: 1125 | J28: 1760 | K28: 427 | N28: 385 | O28: 100 | Q28: 12 отв. ø16 | R28: 1000 | S28: 800 | T28: 860 | U28: 450 | V28: =IFERROR(__xludf.DUMMYFUNCTION("IFERROR(REGEXEXTRACT(A28,""G2-B-(\d+)""),"""")"),"80") -> 80 | W28: =IF(OR(X28="", Y28=""), "", X28+Y28) -> 2 | X28: =IFERROR(__xludf.DUMMYFUNCTION("IFERROR(VALUE(REGEXEXTRACT(A28,""\b(\d+)/\d+\b"")),"""")"),1.0) -> 1 | Y28: =IFERROR(__xludf.DUMMYFUNCTION("IFERROR(VALUE(REGEXEXTRACT(A28,""\b\d+/(\d+)\b"")),"""") "),1.0) -> 1 | Z28: {=IFERROR(INDEX(CRV!BU:BU, MATCH(B28, CRV!A:A, 0)), "")} -> 15 | AA28: {=IFERROR(INDEX(CRV!BV:BV, MATCH(B28, CRV!A:A, 0))*X28+4.5*2+7, "")} -> 43.9 | AB28: {=IFERROR(IF(VALUE(XLOOKUP($B28,CRV!$A:$A,CRV!$BU:$BU))<=5.5,"прямой пуск (DOL)","звезда-треугольник (SD)"),"")} -> звезда-треугольник (SD) | AC28: {=IFERROR(INDEX(CRV!CA:CA, MATCH(B28, CRV!A:A, 0)), "")} -> HQQE | AD28: {=IFERROR(AD27-W28*XLOOKUP($B27,CRV!$A:$A,CRV!$BY:$BY)+W28*XLOOKUP($B28,CRV!$A:$A,CRV!$BY:$BY),"ошибка")} -> 499 | AE28: При заказе
B29: =IFERROR(__xludf.DUMMYFUNCTION("IFERROR(IF(REGEXMATCH(REGEXEXTRACT(A29,""\bCRV\s*\d+(?:-\d+)+(?:-(?:A?BI|AI|BI))?\b""),""-(?:A?BI|AI|BI)$""),REGEXREPLACE(REGEXEXTRACT(A29,""\bCRV\s*\d+(?:-\d+)+(?:-(?:A?BI|AI|BI))?\b""),""-(A?BI|AI|BI)$"",""C$1""),REGEXEXTRACT(A29,""\bCRV\s*\d+(?:-\d+)+("&"?:-(?:A?BI|AI|BI))?\b"")&""C""),"""")"),"") | D29: {=IFERROR(XLOOKUP($B29,CRV!$A:$A,CRV!$BA:$BA)+XLOOKUP($B29,CRV!$A:$A,CRV!$BB:$BB)+$O29,"")} | V29: =IFERROR(__xludf.DUMMYFUNCTION("IFERROR(REGEXEXTRACT(A29,""G2-B-(\d+)""),"""")"),"") | W29: =IF(OR(X29="", Y29=""), "", X29+Y29) | X29: =IFERROR(__xludf.DUMMYFUNCTION("IFERROR(VALUE(REGEXEXTRACT(A29,""\b(\d+)/\d+\b"")),"""")"),"") | Y29: =IFERROR(__xludf.DUMMYFUNCTION("IFERROR(VALUE(REGEXEXTRACT(A29,""\b\d+/(\d+)\b"")),"""") "),"") | Z29: {=IFERROR(INDEX(CRV!BU:BU, MATCH(B29, CRV!A:A, 0)), "")} | AA29: {=IFERROR(INDEX(CRV!BV:BV, MATCH(B29, CRV!A:A, 0))*X29+4.5*2+7, "")} | AB29: {=IFERROR(IF(VALUE(XLOOKUP($B29,CRV!$A:$A,CRV!$BU:$BU))<=5.5,"прямой пуск (DOL)","звезда-треугольник (SD)"),"")} | AC29: {=IFERROR(INDEX(CRV!CA:CA, MATCH(B29, CRV!A:A, 0)), "")}
A30: Hydro-FS-A 1/1 CRV 20-1 G2-B-80-16 | B30: =IFERROR(__xludf.DUMMYFUNCTION("IFERROR(IF(REGEXMATCH(REGEXEXTRACT(A30,""\bCRV\s*\d+(?:-\d+)+(?:-(?:A?BI|AI|BI))?\b""),""-(?:A?BI|AI|BI)$""),REGEXREPLACE(REGEXEXTRACT(A30,""\bCRV\s*\d+(?:-\d+)+(?:-(?:A?BI|AI|BI))?\b""),""-(A?BI|AI|BI)$"",""C$1""),REGEXEXTRACT(A30,""\bCRV\s*\d+(?:-\d+)+("&"?:-(?:A?BI|AI|BI))?\b"")&""C""),"""")"),"CRV 20-1C") -> CRV 20-1C | C30: 1650 | D30: {=IFERROR(XLOOKUP($B30,CRV!$A:$A,CRV!$BA:$BA)+XLOOKUP($B30,CRV!$A:$A,CRV!$BB:$BB)+$O30,"")} -> 672 | E30: 190 | F30: 585 | G30: 540 | H30: 1589 | I30: 1125 | J30: 1760 | K30: 427 | N30: 385 | O30: 100 | Q30: 12 отв. ø16 | R30: 1000 | S30: 800 | T30: 860 | U30: 450 | V30: =IFERROR(__xludf.DUMMYFUNCTION("IFERROR(REGEXEXTRACT(A30,""G2-B-(\d+)""),"""")"),"80") -> 80 | W30: =IF(OR(X30="", Y30=""), "", X30+Y30) -> 2 | X30: =IFERROR(__xludf.DUMMYFUNCTION("IFERROR(VALUE(REGEXEXTRACT(A30,""\b(\d+)/\d+\b"")),"""")"),1.0) -> 1 | Y30: =IFERROR(__xludf.DUMMYFUNCTION("IFERROR(VALUE(REGEXEXTRACT(A30,""\b\d+/(\d+)\b"")),"""") "),1.0) -> 1 | Z30: {=IFERROR(INDEX(CRV!BU:BU, MATCH(B30, CRV!A:A, 0)), "")} -> 1.1 | AA30: {=IFERROR(INDEX(CRV!BV:BV, MATCH(B30, CRV!A:A, 0))*X30+4.5*2+7, "")} -> 20.2 | AB30: {=IFERROR(IF(VALUE(XLOOKUP($B30,CRV!$A:$A,CRV!$BU:$BU))<=5.5,"прямой пуск (DOL)","звезда-треугольник (SD)"),"")} -> прямой пуск (DOL) | AC30: {=IFERROR(INDEX(CRV!CA:CA, MATCH(B30, CRV!A:A, 0)), "")} -> HQQE | AD30: 249 | AE30: 75211373
A31: Hydro-FS-A 1/1 CRV 20-2 G2-B-80-16 | B31: =IFERROR(__xludf.DUMMYFUNCTION("IFERROR(IF(REGEXMATCH(REGEXEXTRACT(A31,""\bCRV\s*\d+(?:-\d+)+(?:-(?:A?BI|AI|BI))?\b""),""-(?:A?BI|AI|BI)$""),REGEXREPLACE(REGEXEXTRACT(A31,""\bCRV\s*\d+(?:-\d+)+(?:-(?:A?BI|AI|BI))?\b""),""-(A?BI|AI|BI)$"",""C$1""),REGEXEXTRACT(A31,""\bCRV\s*\d+(?:-\d+)+("&"?:-(?:A?BI|AI|BI))?\b"")&""C""),"""")"),"CRV 20-2C") -> CRV 20-2C | C31: 1650 | D31: {=IFERROR(XLOOKUP($B31,CRV!$A:$A,CRV!$BA:$BA)+XLOOKUP($B31,CRV!$A:$A,CRV!$BB:$BB)+$O31,"")} -> 769 | E31: 190 | F31: 585 | G31: 540 | H31: 1589 | I31: 1125 | J31: 1760 | K31: 427 | N31: 385 | O31: 100 | Q31: 12 отв. ø16 | R31: 1000 | S31: 800 | T31: 860 | U31: 450 | V31: =IFERROR(__xludf.DUMMYFUNCTION("IFERROR(REGEXEXTRACT(A31,""G2-B-(\d+)""),"""")"),"80") -> 80 | W31: =IF(OR(X31="", Y31=""), "", X31+Y31) -> 2 | X31: =IFERROR(__xludf.DUMMYFUNCTION("IFERROR(VALUE(REGEXEXTRACT(A31,""\b(\d+)/\d+\b"")),"""")"),1.0) -> 1 | Y31: =IFERROR(__xludf.DUMMYFUNCTION("IFERROR(VALUE(REGEXEXTRACT(A31,""\b\d+/(\d+)\b"")),"""") "),1.0) -> 1 | Z31: {=IFERROR(INDEX(CRV!BU:BU, MATCH(B31, CRV!A:A, 0)), "")} -> 2.2 | AA31: {=IFERROR(INDEX(CRV!BV:BV, MATCH(B31, CRV!A:A, 0))*X31+4.5*2+7, "")} -> 23.9 | AB31: {=IFERROR(IF(VALUE(XLOOKUP($B31,CRV!$A:$A,CRV!$BU:$BU))<=5.5,"прямой пуск (DOL)","звезда-треугольник (SD)"),"")} -> прямой пуск (DOL) | AC31: {=IFERROR(INDEX(CRV!CA:CA, MATCH(B31, CRV!A:A, 0)), "")} -> HQQE | AD31: 271 | AE31: 75211401
A32: Hydro-FS-A 1/1 CRV 20-3 G2-B-80-16 | B32: =IFERROR(__xludf.DUMMYFUNCTION("IFERROR(IF(REGEXMATCH(REGEXEXTRACT(A32,""\bCRV\s*\d+(?:-\d+)+(?:-(?:A?BI|AI|BI))?\b""),""-(?:A?BI|AI|BI)$""),REGEXREPLACE(REGEXEXTRACT(A32,""\bCRV\s*\d+(?:-\d+)+(?:-(?:A?BI|AI|BI))?\b""),""-(A?BI|AI|BI)$"",""C$1""),REGEXEXTRACT(A32,""\bCRV\s*\d+(?:-\d+)+("&"?:-(?:A?BI|AI|BI))?\b"")&""C""),"""")"),"CRV 20-3C") -> CRV 20-3C | C32: 1650 | D32: {=IFERROR(XLOOKUP($B32,CRV!$A:$A,CRV!$BA:$BA)+XLOOKUP($B32,CRV!$A:$A,CRV!$BB:$BB)+$O32,"")} -> 867 | E32: 190 | F32: 585 | G32: 540 | H32: 1589 | I32: 1125 | J32: 1760 | K32: 427 | N32: 385 | O32: 100 | Q32: 12 отв. ø16 | R32: 1000 | S32: 800 | T32: 860 | U32: 450 | V32: =IFERROR(__xludf.DUMMYFUNCTION("IFERROR(REGEXEXTRACT(A32,""G2-B-(\d+)""),"""")"),"80") -> 80 | W32: =IF(OR(X32="", Y32=""), "", X32+Y32) -> 2 | X32: =IFERROR(__xludf.DUMMYFUNCTION("IFERROR(VALUE(REGEXEXTRACT(A32,""\b(\d+)/\d+\b"")),"""")"),1.0) -> 1 | Y32: =IFERROR(__xludf.DUMMYFUNCTION("IFERROR(VALUE(REGEXEXTRACT(A32,""\b\d+/(\d+)\b"")),"""") "),1.0) -> 1 | Z32: {=IFERROR(INDEX(CRV!BU:BU, MATCH(B32, CRV!A:A, 0)), "")} -> 4 | AA32: {=IFERROR(INDEX(CRV!BV:BV, MATCH(B32, CRV!A:A, 0))*X32+4.5*2+7, "")} -> 23.8 | AB32: {=IFERROR(IF(VALUE(XLOOKUP($B32,CRV!$A:$A,CRV!$BU:$BU))<=5.5,"прямой пуск (DOL)","звезда-треугольник (SD)"),"")} -> прямой пуск (DOL) | AC32: {=IFERROR(INDEX(CRV!CA:CA, MATCH(B32, CRV!A:A, 0)), "")} -> HQQE | AD32: 299 | AE32: 75211374
A33: Hydro-FS-A 1/1 CRV 20-4 G2-B-80-16 | B33: =IFERROR(__xludf.DUMMYFUNCTION("IFERROR(IF(REGEXMATCH(REGEXEXTRACT(A33,""\bCRV\s*\d+(?:-\d+)+(?:-(?:A?BI|AI|BI))?\b""),""-(?:A?BI|AI|BI)$""),REGEXREPLACE(REGEXEXTRACT(A33,""\bCRV\s*\d+(?:-\d+)+(?:-(?:A?BI|AI|BI))?\b""),""-(A?BI|AI|BI)$"",""C$1""),REGEXEXTRACT(A33,""\bCRV\s*\d+(?:-\d+)+("&"?:-(?:A?BI|AI|BI))?\b"")&""C""),"""")"),"CRV 20-4C") -> CRV 20-4C | C33: 1650 | D33: {=IFERROR(XLOOKUP($B33,CRV!$A:$A,CRV!$BA:$BA)+XLOOKUP($B33,CRV!$A:$A,CRV!$BB:$BB)+$O33,"")} -> 993 | E33: 190 | F33: 585 | G33: 540 | H33: 1589 | I33: 1125 | J33: 1760 | K33: 427 | N33: 385 | O33: 100 | Q33: 12 отв. ø16 | R33: 1000 | S33: 800 | T33: 860 | U33: 450 | V33: =IFERROR(__xludf.DUMMYFUNCTION("IFERROR(REGEXEXTRACT(A33,""G2-B-(\d+)""),"""")"),"80") -> 80 | W33: =IF(OR(X33="", Y33=""), "", X33+Y33) -> 2 | X33: =IFERROR(__xludf.DUMMYFUNCTION("IFERROR(VALUE(REGEXEXTRACT(A33,""\b(\d+)/\d+\b"")),"""")"),1.0) -> 1 | Y33: =IFERROR(__xludf.DUMMYFUNCTION("IFERROR(VALUE(REGEXEXTRACT(A33,""\b\d+/(\d+)\b"")),"""") "),1.0) -> 1 | Z33: {=IFERROR(INDEX(CRV!BU:BU, MATCH(B33, CRV!A:A, 0)), "")} -> 5.5 | AA33: {=IFERROR(INDEX(CRV!BV:BV, MATCH(B33, CRV!A:A, 0))*X33+4.5*2+7, "")} -> 26.6 | AB33: {=IFERROR(IF(VALUE(XLOOKUP($B33,CRV!$A:$A,CRV!$BU:$BU))<=5.5,"прямой пуск (DOL)","звезда-треугольник (SD)"),"")} -> прямой пуск (DOL) | AC33: {=IFERROR(INDEX(CRV!CA:CA, MATCH(B33, CRV!A:A, 0)), "")} -> HQQE | AD33: 329 | AE33: 75211367
A34: Hydro-FS-A 1/1 CRV 20-5 G2-B-80-16 | B34: =IFERROR(__xludf.DUMMYFUNCTION("IFERROR(IF(REGEXMATCH(REGEXEXTRACT(A34,""\bCRV\s*\d+(?:-\d+)+(?:-(?:A?BI|AI|BI))?\b""),""-(?:A?BI|AI|BI)$""),REGEXREPLACE(REGEXEXTRACT(A34,""\bCRV\s*\d+(?:-\d+)+(?:-(?:A?BI|AI|BI))?\b""),""-(A?BI|AI|BI)$"",""C$1""),REGEXEXTRACT(A34,""\bCRV\s*\d+(?:-\d+)+("&"?:-(?:A?BI|AI|BI))?\b"")&""C""),"""")"),"CRV 20-5C") -> CRV 20-5C | C34: 1650 | D34: {=IFERROR(XLOOKUP($B34,CRV!$A:$A,CRV!$BA:$BA)+XLOOKUP($B34,CRV!$A:$A,CRV!$BB:$BB)+$O34,"")} -> 1038 | E34: 190 | F34: 585 | G34: 540 | H34: 1589 | I34: 1125 | J34: 1760 | K34: 427 | N34: 385 | O34: 100 | Q34: 12 отв. ø16 | R34: 1000 | S34: 800 | T34: 860 | U34: 450 | V34: =IFERROR(__xludf.DUMMYFUNCTION("IFERROR(REGEXEXTRACT(A34,""G2-B-(\d+)""),"""")"),"80") -> 80 | W34: =IF(OR(X34="", Y34=""), "", X34+Y34) -> 2 | X34: =IFERROR(__xludf.DUMMYFUNCTION("IFERROR(VALUE(REGEXEXTRACT(A34,""\b(\d+)/\d+\b"")),"""")"),1.0) -> 1 | Y34: =IFERROR(__xludf.DUMMYFUNCTION("IFERROR(VALUE(REGEXEXTRACT(A34,""\b\d+/(\d+)\b"")),"""") "),1.0) -> 1 | Z34: {=IFERROR(INDEX(CRV!BU:BU, MATCH(B34, CRV!A:A, 0)), "")} -> 5.5 | AA34: {=IFERROR(INDEX(CRV!BV:BV, MATCH(B34, CRV!A:A, 0))*X34+4.5*2+7, "")} -> 26.6 | AB34: {=IFERROR(IF(VALUE(XLOOKUP($B34,CRV!$A:$A,CRV!$BU:$BU))<=5.5,"прямой пуск (DOL)","звезда-треугольник (SD)"),"")} -> прямой пуск (DOL) | AC34: {=IFERROR(INDEX(CRV!CA:CA, MATCH(B34, CRV!A:A, 0)), "")} -> HQQE | AD34: 333 | AE34: 75211107
A35: Hydro-FS-A 1/1 CRV 20-6 G2-B-80-16 | B35: =IFERROR(__xludf.DUMMYFUNCTION("IFERROR(IF(REGEXMATCH(REGEXEXTRACT(A35,""\bCRV\s*\d+(?:-\d+)+(?:-(?:A?BI|AI|BI))?\b""),""-(?:A?BI|AI|BI)$""),REGEXREPLACE(REGEXEXTRACT(A35,""\bCRV\s*\d+(?:-\d+)+(?:-(?:A?BI|AI|BI))?\b""),""-(A?BI|AI|BI)$"",""C$1""),REGEXEXTRACT(A35,""\bCRV\s*\d+(?:-\d+)+("&"?:-(?:A?BI|AI|BI))?\b"")&""C""),"""")"),"CRV 20-6C") -> CRV 20-6C | C35: 1650 | D35: {=IFERROR(XLOOKUP($B35,CRV!$A:$A,CRV!$BA:$BA)+XLOOKUP($B35,CRV!$A:$A,CRV!$BB:$BB)+$O35,"")} -> 1121 | E35: 190 | F35: 585 | G35: 540 | H35: 1589 | I35: 1125 | J35: 1760 | K35: 427 | N35: 385 | O35: 100 | Q35: 12 отв. ø16 | R35: 1000 | S35: 800 | T35: 860 | U35: 450 | V35: =IFERROR(__xludf.DUMMYFUNCTION("IFERROR(REGEXEXTRACT(A35,""G2-B-(\d+)""),"""")"),"80") -> 80 | W35: =IF(OR(X35="", Y35=""), "", X35+Y35) -> 2 | X35: =IFERROR(__xludf.DUMMYFUNCTION("IFERROR(VALUE(REGEXEXTRACT(A35,""\b(\d+)/\d+\b"")),"""")"),1.0) -> 1 | Y35: =IFERROR(__xludf.DUMMYFUNCTION("IFERROR(VALUE(REGEXEXTRACT(A35,""\b\d+/(\d+)\b"")),"""") "),1.0) -> 1 | Z35: {=IFERROR(INDEX(CRV!BU:BU, MATCH(B35, CRV!A:A, 0)), "")} -> 7.5 | AA35: {=IFERROR(INDEX(CRV!BV:BV, MATCH(B35, CRV!A:A, 0))*X35+4.5*2+7, "")} -> 30.4 | AB35: {=IFERROR(IF(VALUE(XLOOKUP($B35,CRV!$A:$A,CRV!$BU:$BU))<=5.5,"прямой пуск (DOL)","звезда-треугольник (SD)"),"")} -> звезда-треугольник (SD) | AC35: {=IFERROR(INDEX(CRV!CA:CA, MATCH(B35, CRV!A:A, 0)), "")} -> HQQE | AD35: 349 | AE35: 75211402
A36: Hydro-FS-A 1/1 CRV 20-7 G2-B-80-16 | B36: =IFERROR(__xludf.DUMMYFUNCTION("IFERROR(IF(REGEXMATCH(REGEXEXTRACT(A36,""\bCRV\s*\d+(?:-\d+)+(?:-(?:A?BI|AI|BI))?\b""),""-(?:A?BI|AI|BI)$""),REGEXREPLACE(REGEXEXTRACT(A36,""\bCRV\s*\d+(?:-\d+)+(?:-(?:A?BI|AI|BI))?\b""),""-(A?BI|AI|BI)$"",""C$1""),REGEXEXTRACT(A36,""\bCRV\s*\d+(?:-\d+)+("&"?:-(?:A?BI|AI|BI))?\b"")&""C""),"""")"),"CRV 20-7C") -> CRV 20-7C | C36: 1650 | D36: {=IFERROR(XLOOKUP($B36,CRV!$A:$A,CRV!$BA:$BA)+XLOOKUP($B36,CRV!$A:$A,CRV!$BB:$BB)+$O36,"")} -> 1166 | E36: 190 | F36: 585 | G36: 540 | H36: 1589 | I36: 1125 | J36: 1760 | K36: 427 | N36: 385 | O36: 100 | Q36: 12 отв. ø16 | R36: 1000 | S36: 800 | T36: 860 | U36: 450 | V36: =IFERROR(__xludf.DUMMYFUNCTION("IFERROR(REGEXEXTRACT(A36,""G2-B-(\d+)""),"""")"),"80") -> 80 | W36: =IF(OR(X36="", Y36=""), "", X36+Y36) -> 2 | X36: =IFERROR(__xludf.DUMMYFUNCTION("IFERROR(VALUE(REGEXEXTRACT(A36,""\b(\d+)/\d+\b"")),"""")"),1.0) -> 1 | Y36: =IFERROR(__xludf.DUMMYFUNCTION("IFERROR(VALUE(REGEXEXTRACT(A36,""\b\d+/(\d+)\b"")),"""") "),1.0) -> 1 | Z36: {=IFERROR(INDEX(CRV!BU:BU, MATCH(B36, CRV!A:A, 0)), "")} -> 7.5 | AA36: {=IFERROR(INDEX(CRV!BV:BV, MATCH(B36, CRV!A:A, 0))*X36+4.5*2+7, "")} -> 30.4 | AB36: {=IFERROR(IF(VALUE(XLOOKUP($B36,CRV!$A:$A,CRV!$BU:$BU))<=5.5,"прямой пуск (DOL)","звезда-треугольник (SD)"),"")} -> звезда-треугольник (SD) | AC36: {=IFERROR(INDEX(CRV!CA:CA, MATCH(B36, CRV!A:A, 0)), "")} -> HQQE | AD36: 353 | AE36: 75211377
A37: Hydro-FS-A 1/1 CRV 20-8 G2-B-80-16 | B37: =IFERROR(__xludf.DUMMYFUNCTION("IFERROR(IF(REGEXMATCH(REGEXEXTRACT(A37,""\bCRV\s*\d+(?:-\d+)+(?:-(?:A?BI|AI|BI))?\b""),""-(?:A?BI|AI|BI)$""),REGEXREPLACE(REGEXEXTRACT(A37,""\bCRV\s*\d+(?:-\d+)+(?:-(?:A?BI|AI|BI))?\b""),""-(A?BI|AI|BI)$"",""C$1""),REGEXEXTRACT(A37,""\bCRV\s*\d+(?:-\d+)+("&"?:-(?:A?BI|AI|BI))?\b"")&""C""),"""")"),"CRV 20-8C") -> CRV 20-8C | C37: 1650 | D37: {=IFERROR(XLOOKUP($B37,CRV!$A:$A,CRV!$BA:$BA)+XLOOKUP($B37,CRV!$A:$A,CRV!$BB:$BB)+$O37,"")} -> 1327 | E37: 190 | F37: 585 | G37: 540 | H37: 1589 | I37: 1125 | J37: 1760 | K37: 427 | N37: 385 | O37: 100 | Q37: 12 отв. ø16 | R37: 1000 | S37: 800 | T37: 860 | U37: 450 | V37: =IFERROR(__xludf.DUMMYFUNCTION("IFERROR(REGEXEXTRACT(A37,""G2-B-(\d+)""),"""")"),"80") -> 80 | W37: =IF(OR(X37="", Y37=""), "", X37+Y37) -> 2 | X37: =IFERROR(__xludf.DUMMYFUNCTION("IFERROR(VALUE(REGEXEXTRACT(A37,""\b(\d+)/\d+\b"")),"""")"),1.0) -> 1 | Y37: =IFERROR(__xludf.DUMMYFUNCTION("IFERROR(VALUE(REGEXEXTRACT(A37,""\b\d+/(\d+)\b"")),"""") "),1.0) -> 1 | Z37: {=IFERROR(INDEX(CRV!BU:BU, MATCH(B37, CRV!A:A, 0)), "")} -> 11 | AA37: {=IFERROR(INDEX(CRV!BV:BV, MATCH(B37, CRV!A:A, 0))*X37+4.5*2+7, "")} -> 36.6 | AB37: {=IFERROR(IF(VALUE(XLOOKUP($B37,CRV!$A:$A,CRV!$BU:$BU))<=5.5,"прямой пуск (DOL)","звезда-треугольник (SD)"),"")} -> звезда-треугольник (SD) | AC37: {=IFERROR(INDEX(CRV!CA:CA, MATCH(B37, CRV!A:A, 0)), "")} -> HQQE | AD37: 465 | AE37: 75211403
A38: Hydro-FS-A 1/1 CRV 20-10 G2-B-80-16 | B38: =IFERROR(__xludf.DUMMYFUNCTION("IFERROR(IF(REGEXMATCH(REGEXEXTRACT(A38,""\bCRV\s*\d+(?:-\d+)+(?:-(?:A?BI|AI|BI))?\b""),""-(?:A?BI|AI|BI)$""),REGEXREPLACE(REGEXEXTRACT(A38,""\bCRV\s*\d+(?:-\d+)+(?:-(?:A?BI|AI|BI))?\b""),""-(A?BI|AI|BI)$"",""C$1""),REGEXEXTRACT(A38,""\bCRV\s*\d+(?:-\d+)+("&"?:-(?:A?BI|AI|BI))?\b"")&""C""),"""")"),"CRV 20-10C") -> CRV 20-10C | C38: 1650 | D38: {=IFERROR(XLOOKUP($B38,CRV!$A:$A,CRV!$BA:$BA)+XLOOKUP($B38,CRV!$A:$A,CRV!$BB:$BB)+$O38,"")} -> 1417 | E38: 190 | F38: 585 | G38: 540 | H38: 1589 | I38: 1125 | J38: 1760 | K38: 427 | N38: 385 | O38: 100 | Q38: 12 отв. ø16 | R38: 1000 | S38: 800 | T38: 860 | U38: 450 | V38: =IFERROR(__xludf.DUMMYFUNCTION("IFERROR(REGEXEXTRACT(A38,""G2-B-(\d+)""),"""")"),"80") -> 80 | W38: =IF(OR(X38="", Y38=""), "", X38+Y38) -> 2 | X38: =IFERROR(__xludf.DUMMYFUNCTION("IFERROR(VALUE(REGEXEXTRACT(A38,""\b(\d+)/\d+\b"")),"""")"),1.0) -> 1 | Y38: =IFERROR(__xludf.DUMMYFUNCTION("IFERROR(VALUE(REGEXEXTRACT(A38,""\b\d+/(\d+)\b"")),"""") "),1.0) -> 1 | Z38: {=IFERROR(INDEX(CRV!BU:BU, MATCH(B38, CRV!A:A, 0)), "")} -> 11 | AA38: {=IFERROR(INDEX(CRV!BV:BV, MATCH(B38, CRV!A:A, 0))*X38+4.5*2+7, "")} -> 36.6 | AB38: {=IFERROR(IF(VALUE(XLOOKUP($B38,CRV!$A:$A,CRV!$BU:$BU))<=5.5,"прямой пуск (DOL)","звезда-треугольник (SD)"),"")} -> звезда-треугольник (SD) | AC38: {=IFERROR(INDEX(CRV!CA:CA, MATCH(B38, CRV!A:A, 0)), "")} -> HQQE | AD38: 475 | AE38: 75211404
A39: Hydro-FS-A 1/1 CRV 20-12 G2-B-80-25 | B39: =IFERROR(__xludf.DUMMYFUNCTION("IFERROR(IF(REGEXMATCH(REGEXEXTRACT(A39,""\bCRV\s*\d+(?:-\d+)+(?:-(?:A?BI|AI|BI))?\b""),""-(?:A?BI|AI|BI)$""),REGEXREPLACE(REGEXEXTRACT(A39,""\bCRV\s*\d+(?:-\d+)+(?:-(?:A?BI|AI|BI))?\b""),""-(A?BI|AI|BI)$"",""C$1""),REGEXEXTRACT(A39,""\bCRV\s*\d+(?:-\d+)+("&"?:-(?:A?BI|AI|BI))?\b"")&""C""),"""")"),"CRV 20-12C") -> CRV 20-12C | C39: 1650 | D39: {=IFERROR(XLOOKUP($B39,CRV!$A:$A,CRV!$BA:$BA)+XLOOKUP($B39,CRV!$A:$A,CRV!$BB:$BB)+$O39,"")} -> 1548 | E39: 190 | F39: 585 | G39: 540 | H39: 1589 | I39: 1125 | J39: 1760 | K39: 427 | N39: 385 | O39: 100 | Q39: 12 отв. ø16 | R39: 1000 | S39: 800 | T39: 860 | U39: 450 | V39: =IFERROR(__xludf.DUMMYFUNCTION("IFERROR(REGEXEXTRACT(A39,""G2-B-(\d+)""),"""")"),"80") -> 80 | W39: =IF(OR(X39="", Y39=""), "", X39+Y39) -> 2 | X39: =IFERROR(__xludf.DUMMYFUNCTION("IFERROR(VALUE(REGEXEXTRACT(A39,""\b(\d+)/\d+\b"")),"""")"),1.0) -> 1 | Y39: =IFERROR(__xludf.DUMMYFUNCTION("IFERROR(VALUE(REGEXEXTRACT(A39,""\b\d+/(\d+)\b"")),"""") "),1.0) -> 1 | Z39: {=IFERROR(INDEX(CRV!BU:BU, MATCH(B39, CRV!A:A, 0)), "")} -> 15 | AA39: {=IFERROR(INDEX(CRV!BV:BV, MATCH(B39, CRV!A:A, 0))*X39+4.5*2+7, "")} -> 43.9 | AB39: {=IFERROR(IF(VALUE(XLOOKUP($B39,CRV!$A:$A,CRV!$BU:$BU))<=5.5,"прямой пуск (DOL)","звезда-треугольник (SD)"),"")} -> звезда-треугольник (SD) | AC39: {=IFERROR(INDEX(CRV!CA:CA, MATCH(B39, CRV!A:A, 0)), "")} -> HQQE | AD39: {=IFERROR(AD38-W39*XLOOKUP($B38,CRV!$A:$A,CRV!$BY:$BY)+W39*XLOOKUP($B39,CRV!$A:$A,CRV!$BY:$BY),"ошибка")} -> 505 | AE39: При заказе
A40: Hydro-FS-A 1/1 CRV 20-14 G2-B-80-25 | B40: =IFERROR(__xludf.DUMMYFUNCTION("IFERROR(IF(REGEXMATCH(REGEXEXTRACT(A40,""\bCRV\s*\d+(?:-\d+)+(?:-(?:A?BI|AI|BI))?\b""),""-(?:A?BI|AI|BI)$""),REGEXREPLACE(REGEXEXTRACT(A40,""\bCRV\s*\d+(?:-\d+)+(?:-(?:A?BI|AI|BI))?\b""),""-(A?BI|AI|BI)$"",""C$1""),REGEXEXTRACT(A40,""\bCRV\s*\d+(?:-\d+)+("&"?:-(?:A?BI|AI|BI))?\b"")&""C""),"""")"),"CRV 20-14C") -> CRV 20-14C | C40: 1650 | D40: {=IFERROR(XLOOKUP($B40,CRV!$A:$A,CRV!$BA:$BA)+XLOOKUP($B40,CRV!$A:$A,CRV!$BB:$BB)+$O40,"")} -> 1638 | E40: 190 | F40: 585 | G40: 540 | H40: 1589 | I40: 1125 | J40: 1760 | K40: 427 | N40: 385 | O40: 100 | Q40: 12 отв. ø16 | R40: 1000 | S40: 800 | T40: 860 | U40: 450 | V40: =IFERROR(__xludf.DUMMYFUNCTION("IFERROR(REGEXEXTRACT(A40,""G2-B-(\d+)""),"""")"),"80") -> 80 | W40: =IF(OR(X40="", Y40=""), "", X40+Y40) -> 2 | X40: =IFERROR(__xludf.DUMMYFUNCTION("IFERROR(VALUE(REGEXEXTRACT(A40,""\b(\d+)/\d+\b"")),"""")"),1.0) -> 1 | Y40: =IFERROR(__xludf.DUMMYFUNCTION("IFERROR(VALUE(REGEXEXTRACT(A40,""\b\d+/(\d+)\b"")),"""") "),1.0) -> 1 | Z40: {=IFERROR(INDEX(CRV!BU:BU, MATCH(B40, CRV!A:A, 0)), "")} -> 15 | AA40: {=IFERROR(INDEX(CRV!BV:BV, MATCH(B40, CRV!A:A, 0))*X40+4.5*2+7, "")} -> 43.9 | AB40: {=IFERROR(IF(VALUE(XLOOKUP($B40,CRV!$A:$A,CRV!$BU:$BU))<=5.5,"прямой пуск (DOL)","звезда-треугольник (SD)"),"")} -> звезда-треугольник (SD) | AC40: {=IFERROR(INDEX(CRV!CA:CA, MATCH(B40, CRV!A:A, 0)), "")} -> HQQE | AD40: {=IFERROR(AD39-W40*XLOOKUP($B39,CRV!$A:$A,CRV!$BY:$BY)+W40*XLOOKUP($B40,CRV!$A:$A,CRV!$BY:$BY),"ошибка")} -> 515 | AE40: При заказе
...

Sheet HFS_NBV
